Workbook
Name Segment_POOLER: #N/A
Name Segment_POS: #N/A
Name Segment_SEASON: #N/A

Sheet PTS
AD1: SEASON | AE1: LEADER | AF1: DAYS LED | AG1: STATUS
C2: 2024 | D2: FOW | E2: DEF | F2: GOA | G2: TEAM | H2: PTS | I2: PTS/G | K2: LEAD CHANGE 2024 | L2: DATE | M2: PTS | N2: DL | P2: Gap To Leader | Q2: 2024 | R2: 2023 | S2: 2022 | T2: 2021 | U2: 2020 | V2: 2019 | W2: 2018 | X2: 2017 | Y2: AVG | AD2: 2020 | AE2: DESROSIERS | AF2: 152 | AG2: CHAMP | AJ2: Étiquettes de lignes | AK2: DAYS LED | AL2: SEASONS LED | AM2: Most Recent
A3: 1 | C3: MIOUSSE | D3: =VLOOKUP($C3,'24'!AA:AE,2,FALSE) -> 644 | E3: =VLOOKUP($C3,'24'!AA:AE,3,FALSE) -> 193 | F3: =VLOOKUP($C3,'24'!AA:AE,4,FALSE) -> 88 | G3: =VLOOKUP($C3,'24'!AA:AE,5,FALSE) -> 111 | H3: =SUM(D3:G3) -> 1036 | I3: 1.037 | K3: BLIER | L3: 45210 | M3: 7 | N3: 1 | P3: Winner | Q3: =MAX(H3:H14) -> 1036 | R3: =MAX(H20:H31) -> 1045 | S3: 1011 | T3: 646 | U3: 886 | V3: 999 | W3: 996 | X3: 895 | AD3: 2023 | AE3: DESROSIERS | AF3: 149 | AG3: CHAMP | AI3: 1 | AJ3: DESROSIERS | AK3: 386 | AL3: 4 | AM3: 2023
A4: =A3+1 -> 2 | C4: CHABOT | D4: =VLOOKUP($C4,'24'!AA:AE,2,FALSE) -> 640 | E4: =VLOOKUP($C4,'24'!AA:AE,3,FALSE) -> 182 | F4: =VLOOKUP($C4,'24'!AA:AE,4,FALSE) -> 83 | G4: =VLOOKUP($C4,'24'!AA:AE,5,FALSE) -> 98 | H4: =SUM(D4:G4) -> 1003 | I4: 0.986 | K4: MIOUSSE | L4: 45211 | M4: 17 | N4: 1 | P4: BEAUCHEMIN | Q4: 0.90540541 | R4: =VLOOKUP(P4,$C$19:$I$31,6,FALSE)/$R$3 -> 0.93205742 | S4: 0.96043521 | T4: 0.88544892 | U4: 0.7765237 | V4: 0.96896897 | W4: 1 | X4: 0.94189944 | Y4: =AVERAGE(Q4:X4) -> 0.92134238 | AD4: 2018 | AE4: BEAUCHEMIN | AF4: 142 | AG4: CHAMP | AI4: 2 | AJ4: BLIER | AK4: 154 | AL4: 5 | AM4: 2024
A5: =A4+1 -> 3 | C5: DIEGO | D5: =VLOOKUP($C5,'24'!AA:AE,2,FALSE) -> 640 | E5: =VLOOKUP($C5,'24'!AA:AE,3,FALSE) -> 180 | F5: =VLOOKUP($C5,'24'!AA:AE,4,FALSE) -> 68 | G5: =VLOOKUP($C5,'24'!AA:AE,5,FALSE) -> 104 | H5: =SUM(D5:G5) -> 992 | I5: 1.034 | K5: PICARD | L5: 45212 | M5: 20 | N5: 1 | P5: PICARD | Q5: 0.88610039 | R5: =VLOOKUP(P5,$C$19:$I$31,6,FALSE)/$R$3 -> 0.89665072 | S5: 1 | T5: 0.90712074 | U5: 0.87810384 | V5: 0.86486486 | W5: 0.8624498 | X5: 1 | Y5: =AVERAGE(Q5:X5) -> 0.91191129 | AD5: 2022 | AE5: PICARD | AF5: 102 | AG5: CHAMP | AI5: 3 | AJ5: BEAUCHEMIN | AK5: 150 | AL5: 3 | AM5: 2024
A6: =A5+1 -> 4 | C6: BLIER | D6: =VLOOKUP($C6,'24'!AA:AE,2,FALSE) -> 636 | E6: =VLOOKUP($C6,'24'!AA:AE,3,FALSE) -> 142 | F6: =VLOOKUP($C6,'24'!AA:AE,4,FALSE) -> 60 | G6: =VLOOKUP($C6,'24'!AA:AE,5,FALSE) -> 113 | H6: =SUM(D6:G6) -> 951 | I6: 0.987 | K6: BLIER | L6: 45213 | M6: 24 | N6: 2 | P6: CHABOT | Q6: 0.96814672 | R6: =VLOOKUP(P6,$C$19:$I$31,6,FALSE)/$R$3 -> 0.96650718 | S6: 0.9950544 | T6: 0.81888545 | U6: 0.82167043 | V6: 0.89089089 | W6: 0.90763052 | X6: 0.9027933 | Y6: =AVERAGE(Q6:X6) -> 0.90894736 | AD6: 2024 | AE6: MIOUSSE | AF6: =$N$32 -> 99 | AG6: CHAMP | AI6: 4 | AJ6: PICARD | AK6: 104 | AL6: 3 | AM6: 2024
A7: =A6+1 -> 5 | C7: BEAUCHEMIN | D7: =VLOOKUP($C7,'24'!AA:AE,2,FALSE) -> 599 | E7: =VLOOKUP($C7,'24'!AA:AE,3,FALSE) -> 167 | F7: =VLOOKUP($C7,'24'!AA:AE,4,FALSE) -> 91 | G7: =VLOOKUP($C7,'24'!AA:AE,5,FALSE) -> 81 | H7: =SUM(D7:G7) -> 938 | I7: 0.956 | K7: MIOUSSE | L7: 45214 | M7: 17 | N7: 5 | P7: DESROSIERS | Q7: 0.67760618 | R7: =VLOOKUP(P7,$C$19:$I$31,6,FALSE)/$R$3 -> 1 | S7: 0.76953511 | T7: 1 | U7: 1 | V7: 1 | W7: 0.90361446 | X7: 0.89832402 | Y7: =AVERAGE(Q7:X7) -> 0.90613497 | AD7: 2021 | AE7: BLIER | AF7: 87 | AI7: 5 | AJ7: MIOUSSE | AK7: 103 | AL7: 4 | AM7: 2024
A8: =A7+1 -> 6 | C8: CONSTANTIN | D8: =VLOOKUP($C8,'24'!AA:AE,2,FALSE) -> 562 | E8: =VLOOKUP($C8,'24'!AA:AE,3,FALSE) -> 175 | F8: =VLOOKUP($C8,'24'!AA:AE,4,FALSE) -> 98 | G8: =VLOOKUP($C8,'24'!AA:AE,5,FALSE) -> 98 | H8: =SUM(D8:G8) -> 933 | I8: 0.916 | K8: MOROTTI | L8: 45218 | M8: 51 | N8: 2 | P8: CON/FOR | Q8: 0.90057915 | R8: 0.85263158 | S8: 0.91196835 | T8: 0.82817337 | U8: 0.82844244 | V8: 0.95595596 | W8: 0.95983936 | X8: 0.97653631 | Y8: =AVERAGE(Q8:X8) -> 0.90176581 | AD8: 2019 | AE8: FORCIER | AF8: 77 | AI8: 6 | AJ8: CHABOT | AK8: 87 | AL8: 4 | AM8: 2023
A9: =A8+1 -> 7 | C9: MOROTTI | D9: =VLOOKUP($C9,'24'!AA:AE,2,FALSE) -> 605 | E9: =VLOOKUP($C9,'24'!AA:AE,3,FALSE) -> 147 | F9: =VLOOKUP($C9,'24'!AA:AE,4,FALSE) -> 65 | G9: =VLOOKUP($C9,'24'!AA:AE,5,FALSE) -> 107 | H9: =SUM(D9:G9) -> 924 | I9: 0.959 | K9: DIEGO | L9: 45220 | M9: 62 | N9: 1 | P9: BLIER | Q9: 0.91795367 | R9: =VLOOKUP(P9,$C$19:$I$31,6,FALSE)/$R$3 -> 0.95598086 | S9: 0.88625124 | T9: 0.9752322 | U9: 0.84424379 | V9: 0.86986987 | W9: 0.7811245 | X9: DNP | Y9: =AVERAGE(Q9:X9) -> 0.89009373 | AD9: 2022 | AE9: CHABOT | AF9: 66 | AI9: 7 | AJ9: FORCIER | AK9: 77 | AL9: 1 | AM9: 2019
A10: =A9+1 -> 8 | C10: PICARD | D10: =VLOOKUP($C10,'24'!AA:AE,2,FALSE) -> 576 | E10: =VLOOKUP($C10,'24'!AA:AE,3,FALSE) -> 152 | F10: =VLOOKUP($C10,'24'!AA:AE,4,FALSE) -> 88 | G10: =VLOOKUP($C10,'24'!AA:AE,5,FALSE) -> 102 | H10: =SUM(D10:G10) -> 918 | I10: 0.952 | K10: BEAUCHEMIN | L10: 45221 | M10: 77 | N10: 1 | P10: MIOUSSE | Q10: 1 | R10: =VLOOKUP(P10,$C$19:$I$31,6,FALSE)/$R$3 -> 0.88229665 | S10: 0.884273 | T10: 0.88544892 | U10: 0.81602709 | V10: 0.79479479 | W10: 0.84437751 | X10: 0.83687151 | Y10: =AVERAGE(Q10:X10) -> 0.86801118 | AD10: 2019 | AE10: DESROSIERS | AF10: 56 | AG10: CHAMP | AI10: 8 | AJ10: DIEGO | AK10: 66 | AL10: 3 | AM10: 2024
A11: =A10+1 -> 9 | C11: LESSARD | D11: =VLOOKUP($C11,'24'!AA:AE,2,FALSE) -> 555 | E11: =VLOOKUP($C11,'24'!AA:AE,3,FALSE) -> 143 | F11: =VLOOKUP($C11,'24'!AA:AE,4,FALSE) -> 72 | G11: =VLOOKUP($C11,'24'!AA:AE,5,FALSE) -> 109 | H11: =SUM(D11:G11) -> 879 | I11: 0.902 | K11: LESSARD | L11: 45222 | M11: 79 | N11: 2 | P11: MOROTTI | Q11: 0.89189189 | R11: =VLOOKUP(P11,$C$19:$I$31,6,FALSE)/$R$3 -> 0.80574163 | S11: 0.86547972 | T11: 0.93188854 | U11: 0.82167043 | V11: 0.82382382 | W11: 0.8373494 | X11: 0.8972067 | Y11: =AVERAGE(Q11:X11) -> 0.85938152 | AD11: 2019 | AE11: HENAULT | AF11: 54 | AI11: 9 | AJ11: HENAULT | AK11: 54 | AL11: 1 | AM11: 2019
A12: =A11+1 -> 10 | C12: HENAULT | D12: =VLOOKUP($C12,'24'!AA:AE,2,FALSE) -> 486 | E12: =VLOOKUP($C12,'24'!AA:AE,3,FALSE) -> 150 | F12: =VLOOKUP($C12,'24'!AA:AE,4,FALSE) -> 83 | G12: =VLOOKUP($C12,'24'!AA:AE,5,FALSE) -> 110 | H12: =SUM(D12:G12) -> 829 | I12: 0.88 | K12: DIEGO | L12: 45224 | M12: 94 | N12: 3 | P12: LESSARD | Q12: 0.8484556 | R12: =VLOOKUP(P12,$C$19:$I$31,6,FALSE)/$R$3 -> 0.8076555 | S12: 0.88031652 | T12: 0.95665635 | U12: 0.74943567 | V12: 0.75975976 | W12: 0.81726908 | X12: 0.92067039 | Y12: =AVERAGE(Q12:X12) -> 0.84252736 | AD12: 2024 | AE12: DIEGO | AF12: 41 | AI12: 10 | AJ12: CONSTANTIN | AK12: 31 | AL12: 2 | AM12: 2024
A13: =A12+1 -> 11 | C13: ROBB | D13: =VLOOKUP($C13,'24'!AA:AE,2,FALSE) -> 587 | E13: =VLOOKUP($C13,'24'!AA:AE,3,FALSE) -> 109 | F13: =VLOOKUP($C13,'24'!AA:AE,4,FALSE) -> 22 | G13: =VLOOKUP($C13,'24'!AA:AE,5,FALSE) -> 47 | H13: =SUM(D13:G13) -> 765 | I13: 0.787 | K13: BEAUCHEMIN | L13: 45226 | M13: 103 | N13: 3 | P13: DIEGO | Q13: 0.95752896 | R13: =VLOOKUP(P13,$C$19:$I$31,6,FALSE)/$R$3 -> 0.93397129 | S13: 0.88526212 | T13: 0.81424149 | U13: 0.7234763 | V13: 0.78078078 | W13: 0.80421687 | X13: 0.81564246 | Y13: =AVERAGE(Q13:X13) -> 0.83939003 | AD13: 2024 | AE13: BLIER | AF13: 35 | AI13: 11 | AJ13: LESSARD | AK13: 19 | AL13: 2 | AM13: 2024
A14: =A13+1 -> 12 | C14: DESROSIERS | D14: =VLOOKUP($C14,'24'!AA:AE,2,FALSE) -> 447 | E14: =VLOOKUP($C14,'24'!AA:AE,3,FALSE) -> 110 | F14: =VLOOKUP($C14,'24'!AA:AE,4,FALSE) -> 93 | G14: =VLOOKUP($C14,'24'!AA:AE,5,FALSE) -> 52 | H14: =SUM(D14:G14) -> 702 | I14: 0.743 | K14: DIEGO | L14: 45228 | M14: 114 | N14: 5 | P14: HENAULT | Q14: 0.80019305 | R14: =VLOOKUP(P14,$C$19:$I$31,6,FALSE)/$R$3 -> 0.77416268 | S14: 0.83481701 | T14: 0.82817337 | U14: 0.80699774 | V14: 0.91191191 | W14: 0.89257028 | X14: 0.77988827 | Y14: =AVERAGE(Q14:X14) -> 0.82858929 | AD14: 2021 | AE14: DESROSIERS | AF14: 29 | AG14: CHAMP | AI14: 12 | AJ14: MOROTTI | AK14: 16 | AL14: 3 | AM14: 2024
K15: BEAUCHEMIN | L15: 45230 | M15: 103 | N15: 6 | P15: ROB/DAV | Q15: 0.73841699 | R15: 0.7722488 | S15: 0.8793274 | T15: 0.79411765 | U15: 0.84988713 | V15: 0.87287287 | W15: DNP | X15: DNP | Y15: =AVERAGE(Q15:X15) -> 0.81781181 | AD15: 2022 | AE15: CONSTANTIN | AF15: 26 | AI15: 13 | AJ15: ROBB | AK15: 7 | AL15: 1 | AM15: 2022
C16: AVG | D16: =AVERAGE(D3:D15) -> 581.41667 | E16: =AVERAGE(E3:E15) -> 154.16667 | F16: =AVERAGE(F3:F15) -> 75.916667 | G16: =AVERAGE(G3:G15) -> 94.333333 | H16: =AVERAGE(H3:H15) -> 905.83333 | I16: =AVERAGE(I3:I15) -> 0.92825 | K16: DIEGO | L16: 45233 | M16: 134 | N16: 7 | P16: AVG | Q16: =AVERAGE(Q4:Q15) -> 0.8743565 | R16: =AVERAGE(R4:R15) -> 0.88165869 | S16: =AVERAGE(S4:S15) -> 0.89606001 | T16: =AVERAGE(T4:T15) -> 0.88544892 | U16: =AVERAGE(U4:U15) -> 0.82637321 | V16: =AVERAGE(V4:V15) -> 0.87454121 | W16: =AVERAGE(W4:W15) -> 0.87367652 | X16: =AVERAGE(X4:X15) -> 0.89698324 | AD16: 2023 | AE16: BLIER | AF16: 24 | AJ16: (vide)
K17: BLIER | L17: 45235 | M17: 144 | N17: 4 | AD17: 2018 | AE17: DIEGO | AF17: 24 | AJ17: Total général | AK17: 1254 | AL17: 36 | AM17: 2024
K18: CONSTANTIN | L18: 45237 | M18: 155 | N18: 3 | P18: Gap To Leader | Q18: 2024 | R18: 2023 | S18: 2022 | T18: 2021 | U18: 2020 | V18: 2019 | W18: 2018 | X18: 2017 | Y18: AVG | AD18: 2021 | AE18: LESSARD | AF18: 17
C19: 2023 | D19: FOW | E19: DEF | F19: GOA | G19: TEAM | H19: PTS | I19: PTS/G | K19: BLIER | L19: 45240 | M19: 173 | N19: 6 | P19: Winner | Q19: 1036 | R19: 1045 | S19: 1011 | T19: 646 | U19: 886 | V19: 999 | W19: 996 | X19: 895 | AD19: 2018 | AE19: CHABOT | AF19: 10
A20: 1 | C20: DESROSIERS | D20: 694 | E20: 178 | F20: 66 | G20: 107 | H20: =SUM(D20:G20) -> 1045 | I20: 1.0429142 | K20: MIOUSSE | L20: 45242 | M20: 186 | N20: 6 | P20: BEAUCHEMIN | Q20: 98 | R20: 71 | S20: =$S$19-VLOOKUP(P20,$C$37:$H$48,6,FALSE) -> 40 | T20: =$T$19-VLOOKUP(P20,$C$54:$H$65,6,FALSE) -> 74 | U20: =$U$19-VLOOKUP(P20,$C$71:$H$82,6,FALSE) -> 198 | V20: =$V$19-VLOOKUP(P20,$C$88:$H$99,6,FALSE) -> 31 | W20: =$W$19-VLOOKUP(P20,$C$105:$H$116,6,FALSE) -> 0 | X20: =$X$19-VLOOKUP(P20,$C$121:$H$132,6,FALSE) -> 52 | Y20: =AVERAGE(Q20:X20) -> 70.5 | AD20: 2018 | AE20: MOROTTI | AF20: 10
A21: =A20+1 -> 2 | C21: CHABOT | D21: 613 | E21: 186 | F21: 102 | G21: 109 | H21: =SUM(D21:G21) -> 1010 | I21: 0.99311701 | K21: CONSTANTIN | L21: 45243 | M21: 155 | N21: 5 | P21: CHABOT | Q21: 33 | R21: 35 | S21: =$S$19-VLOOKUP(P21,$C$37:$H$48,6,FALSE) -> 5 | T21: =$T$19-VLOOKUP(P21,$C$54:$H$65,6,FALSE) -> 117 | U21: =$U$19-VLOOKUP(P21,$C$71:$H$82,6,FALSE) -> 158 | V21: =$V$19-VLOOKUP(P21,$C$88:$H$99,6,FALSE) -> 109 | W21: =$W$19-VLOOKUP(P21,$C$105:$H$116,6,FALSE) -> 92 | X21: =$X$19-VLOOKUP(P21,$C$121:$H$132,6,FALSE) -> 87 | Y21: =AVERAGE(Q21:X21) -> 79.5 | AD21: 2023 | AE21: CHABOT | AF21: 8
A22: =A21+1 -> 3 | C22: BLIER | D22: 661 | E22: 181 | F22: 44 | G22: 113 | H22: =SUM(D22:G22) -> 999 | I22: 1.0384615 | K22: BLIER | L22: 45245 | M22: 202 | N22: 29 | P22: PICARD | Q22: 118 | R22: 108 | S22: =$S$19-VLOOKUP(P22,$C$37:$H$48,6,FALSE) -> 0 | T22: =$T$19-VLOOKUP(P22,$C$54:$H$65,6,FALSE) -> 60 | U22: =$U$19-VLOOKUP(P22,$C$71:$H$82,6,FALSE) -> 108 | V22: =$V$19-VLOOKUP(P22,$C$88:$H$99,6,FALSE) -> 135 | W22: =$W$19-VLOOKUP(P22,$C$105:$H$116,6,FALSE) -> 137 | X22: =$X$19-VLOOKUP(P22,$C$121:$H$132,6,FALSE) -> 0 | Y22: =AVERAGE(Q22:X22) -> 83.25 | AD22: 2022 | AE22: ROBB | AF22: 7
A23: =A22+1 -> 4 | C23: DIEGO | D23: 648 | E23: 146 | F23: 89 | G23: 93 | H23: =SUM(D23:G23) -> 976 | I23: 0.98486377 | K23: DIEGO | L23: 45268 | M23: 322 | N23: 21 | P23: CON/FOR | Q23: 103 | R23: 154 | S23: 89 | T23: 83 | U23: 152 | V23: 44 | W23: 40 | X23: 21 | Y23: =AVERAGE(Q23:X23) -> 85.75 | AD23: 2020 | AE23: BLIER | AF23: 7
A24: =A23+1 -> 5 | C24: BEAUCHEMIN | D24: 613 | E24: 192 | F24: 88 | G24: 81 | H24: =SUM(D24:G24) -> 974 | I24: 0.96819085 | K24: BLIER | L24: 45282 | M24: 398 | N24: 35 | P24: DESROSIERS | Q24: 334 | R24: 0 | S24: =$S$19-VLOOKUP(P24,$C$37:$H$48,6,FALSE) -> 233 | T24: =$T$19-VLOOKUP(P24,$C$54:$H$65,6,FALSE) -> 0 | U24: =$U$19-VLOOKUP(P24,$C$71:$H$82,6,FALSE) -> 0 | V24: =$V$19-VLOOKUP(P24,$C$88:$H$99,6,FALSE) -> 0 | W24: =$W$19-VLOOKUP(P24,$C$105:$H$116,6,FALSE) -> 96 | X24: =$X$19-VLOOKUP(P24,$C$121:$H$132,6,FALSE) -> 91 | Y24: =AVERAGE(Q24:X24) -> 94.25 | AD24: 2024 | AE24: BEAUCHEMIN | AF24: 6
A25: =A24+1 -> 6 | C25: PICARD | D25: 610 | E25: 133 | F25: 103 | G25: 91 | H25: =SUM(D25:G25) -> 937 | I25: 0.93141153 | K25: DIEGO | L25: 45288 | M25: 420 | N25: 22 | P25: BLIER | Q25: 85 | R25: 46 | S25: =$S$19-VLOOKUP(P25,$C$37:$H$48,6,FALSE) -> 115 | T25: =$T$19-VLOOKUP(P25,$C$54:$H$65,6,FALSE) -> 16 | U25: =$U$19-VLOOKUP(P25,$C$71:$H$82,6,FALSE) -> 138 | V25: =$V$19-VLOOKUP(P25,$C$88:$H$99,6,FALSE) -> 130 | W25: =$W$19-VLOOKUP(P25,$C$105:$H$116,6,FALSE) -> 218 | X25: DNP | Y25: =AVERAGE(Q25:X25) -> 106.85714 | AD25: 2024 | AE25: CONSTANTIN | AF25: 5
A26: =A25+1 -> 7 | C26: MIOUSSE | D26: 572 | E26: 150 | F26: 97 | G26: 103 | H26: =SUM(D26:G26) -> 922 | I26: 0.94370522 | K26: MIOUSSE | L26: 45289 | M26: 427 | N26: 9 | P26: MIOUSSE | Q26: 0 | R26: 123 | S26: =$S$19-VLOOKUP(P26,$C$37:$H$48,6,FALSE) -> 117 | T26: =$T$19-VLOOKUP(P26,$C$54:$H$65,6,FALSE) -> 74 | U26: =$U$19-VLOOKUP(P26,$C$71:$H$82,6,FALSE) -> 163 | V26: =$V$19-VLOOKUP(P26,$C$88:$H$99,6,FALSE) -> 205 | W26: =$W$19-VLOOKUP(P26,$C$105:$H$116,6,FALSE) -> 155 | X26: =$X$19-VLOOKUP(P26,$C$121:$H$132,6,FALSE) -> 146 | Y26: =AVERAGE(Q26:X26) -> 122.875 | AD26: 2023 | AE26: MOROTTI | AF26: 4
A27: =A26+1 -> 8 | C27: CONSTANTIN | D27: 579 | E27: 149 | F27: 54 | G27: 109 | H27: =SUM(D27:G27) -> 891 | I27: 0.888335 | K27: DIEGO | L27: 45292 | M27: 450 | N27: 27 | P27: MOROTTI | Q27: 112 | R27: 203 | S27: =$S$19-VLOOKUP(P27,$C$37:$H$48,6,FALSE) -> 136 | T27: =$T$19-VLOOKUP(P27,$C$54:$H$65,6,FALSE) -> 44 | U27: =$U$19-VLOOKUP(P27,$C$71:$H$82,6,FALSE) -> 158 | V27: =$V$19-VLOOKUP(P27,$C$88:$H$99,6,FALSE) -> 176 | W27: =$W$19-VLOOKUP(P27,$C$105:$H$116,6,FALSE) -> 162 | X27: =$X$19-VLOOKUP(P27,$C$121:$H$132,6,FALSE) -> 92 | Y27: =AVERAGE(Q27:X27) -> 135.375 | AD27: 2021 | AE27: CHABOT | AF27: 3
A28: =A27+1 -> 9 | C28: LESSARD | D28: 523 | E28: 151 | F28: 75 | G28: 95 | H28: =SUM(D28:G28) -> 844 | I28: 0.87190083 | K28: MIOUSSE | L28: 45297 | M28: 478 | N28: 63 | P28: DIEGO | Q28: 44 | R28: 69 | S28: =$S$19-VLOOKUP(P28,$C$37:$H$48,6,FALSE) -> 116 | T28: =$T$19-VLOOKUP(P28,$C$54:$H$65,6,FALSE) -> 120 | U28: =$U$19-VLOOKUP(P28,$C$71:$H$82,6,FALSE) -> 245 | V28: =$V$19-VLOOKUP(P28,$C$88:$H$99,6,FALSE) -> 219 | W28: =$W$19-VLOOKUP(P28,$C$105:$H$116,6,FALSE) -> 195 | X28: =$X$19-VLOOKUP(P28,$C$121:$H$132,6,FALSE) -> 165 | Y28: =AVERAGE(Q28:X28) -> 146.625 | AD28: 2023 | AE28: BEAUCHEMIN | AF28: 2
A29: =A28+1 -> 10 | C29: MOROTTI | D29: 551 | E29: 100 | F29: 93 | G29: 98 | H29: =SUM(D29:G29) -> 842 | I29: 0.85136502 | K29: DIEGO | L29: 45351 | M29: 736 | N29: 28 | P29: LESSARD | Q29: 157 | R29: 201 | S29: =$S$19-VLOOKUP(P29,$C$37:$H$48,6,FALSE) -> 121 | T29: =$T$19-VLOOKUP(P29,$C$54:$H$65,6,FALSE) -> 28 | U29: =$U$19-VLOOKUP(P29,$C$71:$H$82,6,FALSE) -> 222 | V29: =$V$19-VLOOKUP(P29,$C$88:$H$99,6,FALSE) -> 240 | W29: =$W$19-VLOOKUP(P29,$C$105:$H$116,6,FALSE) -> 182 | X29: =$X$19-VLOOKUP(P29,$C$121:$H$132,6,FALSE) -> 71 | Y29: =AVERAGE(Q29:X29) -> 152.75 | AD29: 2021 | AE29: MIOUSSE | AF29: 2
A30: =A29+1 -> 11 | C30: HENAULT | D30: 450 | E30: 160 | F30: 88 | G30: 111 | H30: =SUM(D30:G30) -> 809 | I30: 0.86709539 | K30: MIOUSSE | L30: 45352 | M30: 744 | N30: 65 | P30: HENAULT | Q30: 207 | R30: 236 | S30: =$S$19-VLOOKUP(P30,$C$37:$H$48,6,FALSE) -> 167 | T30: =$T$19-VLOOKUP(P30,$C$54:$H$65,6,FALSE) -> 111 | U30: =$U$19-VLOOKUP(P30,$C$71:$H$82,6,FALSE) -> 171 | V30: =$V$19-VLOOKUP(P30,$C$88:$H$99,6,FALSE) -> 88 | W30: =$W$19-VLOOKUP(P30,$C$105:$H$116,6,FALSE) -> 107 | X30: =$X$19-VLOOKUP(P30,$C$121:$H$132,6,FALSE) -> 197 | Y30: =AVERAGE(Q30:X30) -> 160.5 | AD30: 2024 | AE30: MOROTTI | AF30: 2
A31: =A30+1 -> 12 | C31: ROBB | D31: 478 | E31: 164 | F31: 73 | G31: 92 | H31: =SUM(D31:G31) -> 807 | I31: 0.81928934 | K31: DIEGO | L31: 45354 | M31: 751 | N31: 41 | P31: ROB/DAV | Q31: 271 | R31: 238 | S31: 122 | T31: 133 | U31: 133 | V31: 127 | W31: DNP | X31: DNP | Y31: =AVERAGE(Q31:X31) -> 170.66667 | AD31: 2024 | AE31: LESSARD | AF31: 2
K32: MIOUSSE | L32: 45367 | M32: 810 | N32: 99 | P32: AVG | Q32: =AVERAGE(Q20:Q31) -> 130.16667 | R32: =AVERAGE(R20:R31) -> 123.66667 | S32: =AVERAGE(S20:S31) -> 105.08333 | T32: =AVERAGE(T20:T31) -> 71.666667 | U32: =AVERAGE(U20:U31) -> 153.83333 | V32: =AVERAGE(V20:V31) -> 125.33333 | W32: =AVERAGE(W20:W31) -> 125.81818 | X32: =AVERAGE(X20:X31) -> 92.2 | AD32: 2018 | AE32: MIOUSSE | AF32: 1
C33: AVG | D33: =AVERAGE(D20:D32) -> 582.66667 | E33: =AVERAGE(E20:E32) -> 157.5 | F33: =AVERAGE(F20:F32) -> 81 | G33: =AVERAGE(G20:G32) -> 100.16667 | H33: =AVERAGE(H20:H32) -> 921.33333 | I33: =AVERAGE(I20:I32) -> 0.93338747 | AD33: 2023 | AE33: PICARD | AF33: 1
AD34: 2021 | AE34: DIEGO | AF34: 1
K35: LEAD CHANGE 2023 | L35: DATE | M35: PTS | N35: DL | AD35: 2019 | AE35: BLIER | AF35: 1
C36: 2022 | D36: FOW | E36: DEF | F36: GOA | G36: TEAM | H36: PTS | I36: PTS/G | K36: PICARD | L36: 44842 | M36: 2 | N36: 1 | AD36: 2023 | AE36: MIOUSSE | AF36: 1
A37: 1 | C37: PICARD | D37: 626 | E37: 179 | F37: 93 | G37: 113 | H37: 1011 | I37: 1.06 | K37: MOROTTI | L37: 44843 | M37: 3 | N37: 4 | AD37: 2024 | AE37: PICARD | AF37: 1
A38: =A37+1 -> 2 | C38: CHABOT | D38: 632 | E38: 159 | F38: 93 | G38: 122 | H38: 1006 | I38: 1.03 | K38: DESROSIERS | L38: 44847 | M38: 16 | N38: 10
A39: =A38+1 -> 3 | C39: BEAUCHEMIN | D39: 617 | E39: 169 | F39: 96 | G39: 89 | H39: 971 | I39: 0.997 | K39: CHABOT | L39: 44857 | M39: 80 | N39: 1
A40: =A39+1 -> 4 | C40: CONSTANTIN | D40: 557 | E40: 171 | F40: 90 | G40: 104 | H40: 922 | I40: 0.98 | K40: DESROSIERS | L40: 44858 | M40: 81 | N40: 11
...

Sheet W2W
A2: 2024 | B2: 1 | C2: PTS | D2: 2 | E2: PTS | F2: 3 | G2: PTS | H2: 4 | I2: PTS | J2: 5 | K2: PTS | L2: 6 | M2: PTS | N2: 7 | O2: PTS | P2: 8 | Q2: PTS | R2: 9 | S2: PTS | T2: 10 | U2: PTS | V2: 11 | W2: PTS | X2: 12 | Y2: PTS
A3: 1 | B3: MIOUSSE | C3: 43 | D3: LESSARD | E3: 39 | F3: MOROTTI | G3: 39 | H3: CHABOT | I3: 39 | J3: BLIER | K3: 38 | L3: DIEGO | M3: 37 | N3: PICARD | O3: 37 | P3: CONSTANTIN | Q3: 32 | R3: BEAUCHEMIN | S3: 30 | T3: ROBB | U3: 29 | V3: HENAULT | W3: 28 | X3: DESROSIERS | Y3: 23
A4: 2 | B4: LESSARD (40) | C4: 79 | D4: BEAUCHEMIN (49) | E4: 79 | F4: DIEGO (40) | G4: 77 | H4: MOROTTI (34) | I4: 73 | J4: BLIER (34) | K4: 72 | L4: PICARD (33) | M4: 70 | N4: CHABOT (28) | O4: 67 | P4: CONSTANTIN (34) | Q4: 66 | R4: MIOUSSE (18) | S4: 61 | T4: HENAULT (26) | U4: 54 | V4: ROBB (21) | W4: 50 | X4: DESROSIERS (25) | Y4: 48
A5: 3 | B5: BEAUCHEMIN (46) | C5: 125 | D5: DIEGO (46) | E5: 123 | F5: LESSARD (41) | G5: 120 | H5: CHABOT (52) | I5: 119 | J5: CONSTANTIN (45) | K5: 111 | L5: BLIER (39) | M5: 111 | N5: PICARD (41) | O5: 111 | P5: MIOUSSE (46) | Q5: 107 | R5: MOROTTI (31) | S5: 104 | T5: HENAULT (40) | U5: 94 | V5: DESROSIERS (36) | W5: 84 | X5: ROBB (27) | Y5: 77
A6: 4 | B6: CONSTANTIN (44) | C6: 155 | D6: MIOUSSE (47) | E6: 154 | F6: BLIER (40) | G6: 151 | H6: BEAUCHEMIN (24) | I6: 149 | J6: DIEGO (25) | K6: 148 | L6: CHABOT (26) | M6: 145 | N6: PICARD (34) | O6: 145 | P6: LESSARD (20) | Q6: 140 | R6: MOROTTI (30) | S6: 134 | T6: HENAULT (32) | U6: 126 | V6: DESROSIERS (21) | W6: 105 | X6: ROBB (28) | Y6: 105
A7: 5 | B7: CONSTANTIN (38) | C7: 193 | D7: MIOUSSE (36) | E7: 190 | F7: BLIER (38) | G7: 189 | H7: BEAUCHEMIN (38) | I7: 187 | J7: DIEGO (37) | K7: 185 | L7: LESSARD (44) | M7: 184 | N7: PICARD (34) | O7: 179 | P7: CHABOT (33) | Q7: 178 | R7: MOROTTI (29) | S7: 163 | T7: HENAULT (32) | U7: 158 | V7: ROBB (37) | W7: 142 | X7: DESROSIERS (33) | Y7: 138
A8: 6 | B8: BLIER (52) | C8: 241 | D8: DIEGO (44) | E8: 229 | F8: CONSTANTIN (35) | G8: 228 | H8: BEAUCHEMIN (39) | I8: 226 | J8: MIOUSSE (36) | K8: 226 | L8: LESSARD (33) | M8: 217 | N8: PICARD (38) | O8: 217 | P8: CHABOT (28) | Q8: 206 | R8: MOROTTI (41) | S8: 204 | T8: HENAULT (37) | U8: 195 | V8: ROBB (30) | W8: 172 | X8: DESROSIERS (18) | Y8: 156
A9: 7 | B9: BLIER (29) | C9: 270 | D9: CONSTANTIN (33) | E9: 261 | F9: BEAUCHEMIN (32) | G9: 258 | H9: MIOUSSE (31) | I9: 257 | J9: DIEGO (27) | K9: 256 | L9: LESSARD (32) | M9: 249 | N9: PICARD (31) | O9: 248 | P9: CHABOT (34) | Q9: 240 | R9: MOROTTI (30) | S9: 234 | T9: HENAULT (33) | U9: 228 | V9: ROBB (25) | W9: 197 | X9: DESROSIERS (21) | Y9: 177
A10: 8 | B10: BLIER (37) | C10: 307 | D10: DIEGO (43) | E10: 299 | F10: CONSTANTIN (30) | G10: 291 | H10: MIOUSSE (33) | I10: 290 | J10: LESSARD (40) | K10: 289 | L10: BEAUCHEMIN (30) | M10: 288 | N10: PICARD (34) | O10: 282 | P10: CHABOT (40) | Q10: 280 | R10: MOROTTI (33) | S10: 267 | T10: HENAULT (36) | U10: 264 | V10: ROBB (34) | W10: 231 | X10: DESROSIERS (26) | Y10: 203
A11: 9 | B11: DIEGO (44) | C11: 343 | D11: BLIER (30) | E11: 337 | F11: CONSTANTIN (42) | G11: 333 | H11: BEAUCHEMIN (37) | I11: 325 | J11: PICARD (40) | K11: 322 | L11: LESSARD (28) | M11: 317 | N11: MIOUSSE (25) | O11: 315 | P11: CHABOT (33) | Q11: 313 | R11: MOROTTI (35) | S11: 302 | T11: HENAULT (32) | U11: 296 | V11: ROBB (42) | W11: 273 | X11: DESROSIERS (27) | Y11: 230
A12: 10 | B12: DIEGO (37) | C12: 380 | D12: BLIER (41) | E12: 378 | F12: PICARD (47) | G12: 369 | H12: CONSTANTIN (28) | I12: 361 | J12: MIOUSSE (44) | K12: 359 | L12: BEAUCHEMIN (31) | M12: 356 | N12: CHABOT (37) | O12: 350 | P12: LESSARD (29) | Q12: 346 | R12: MOROTTI (27) | S12: 329 | T12: HENAULT (33) | U12: 329 | V12: ROBB (31) | W12: 304 | X12: DESROSIERS (20) | Y12: 250
A13: 11 | B13: BLIER (33) | C13: 411 | D13: DIEGO (30) | E13: 410 | F13: PICARD (33) | G13: 402 | H13: MIOUSSE (36) | I13: 395 | J13: CONSTANTIN (31) | K13: 392 | L13: CHABOT (37) | M13: 387 | N13: BEAUCHEMIN (30) | O13: 386 | P13: LESSARD (28) | Q13: 374 | R13: HENAULT (30) | S13: 359 | T13: MOROTTI (23) | U13: 352 | V13: ROBB (23) | W13: 327 | X13: DESROSIERS (33) | Y13: 283
A14: 12 | B14: DIEGO (41) | C14: 451 | D14: MIOUSSE (53) | E14: 448 | F14: BLIER (25) | G14: 436 | H14: CONSTANTIN (36) | I14: 428 | J14: PICARD (20) | K14: 422 | L14: BEAUCHEMIN (35) | M14: 421 | N14: LESSARD (46) | O14: 420 | P14: CHABOT (22) | Q14: 409 | R14: HENAULT (34) | S14: 393 | T14: MOROTTI (23) | U14: 375 | V14: ROBB (25) | W14: 352 | X14: DESROSIERS (25) | Y14: 308
... A28: 26 | B28: MIOUSE (42) | C28: 1027 | D28: CHABOT (57) | E28: 993 | F28: DIEGO (32) | G28: 986 | H28: BLIER (29) | I28: 939 | J28: CONSTANTIN (34) | K28: 928 | L28: BEAUCHEMIN (35) | M28: 927 | N28: MOROTTI (33) | O28: 913 | P28: PICARD (39) | Q28: 910 | R28: LESSARD (39) | S28: 868 | T28: HENAULT (31) | U28: 819 | V28: ROBB (25) | W28: 756 | X28: DESROSIERS (31) | Y28: 695
A29: END | B29: MIOUSE | C29: 1027 | D29: CHABOT | E29: 1003 | F29: DIEGO | G29: 993 | H29: BLIER | I29: 951 | J29: BEAUCHEMIN | K29: 938 | L29: CONSTANTIN | M29: 933 | N29: MOROTTI | O29: 924 | P29: PICARD | Q29: 878 | R29: LESSARD | S29: 787 | T29: HENAULT | U29: 929 | V29: ROBB | W29: 765 | X29: DESROSIERS | Y29: 702

Sheet W2WC
BC1: Season | BD1: Week | BE1: DATE | BF1: POOLER | BG1: PTS
B2: WEEK 2 WEEK CUP 2023 | AH2: SCORING | AK2: W2W CUP Stats | AL2: Wins | AM2: Pod | AN2: Last | AO2: Champ | AR2: Most Points in a week | AV2: Last Win | AW2: POOLER | AX2: Weeks | AY2: Days | BC2: 2022 | BD2: 1 | BE2: 44488 | BF2: CHABOT | BG2: 43
B3: POOLER/WEEK | C3: 1 | D3: 2 | E3: 3 | F3: 4 | G3: 5 | H3: 6 | I3: 7 | J3: 8 | K3: 9 | L3: 10 | M3: 11 | N3: 12 | O3: 13 | P3: 14 | Q3: 15 | R3: 16 | S3: 17 | T3: 18 | U3: 19 | V3: 20 | W3: 21 | X3: 22 | Y3: 23 | Z3: 24 | AA3: 25 | AB3: 26 | AC3: TOTAL | AD3: AVG | AE3: W | AF3: PD | AH3: PLACE | AI3: POINTS | AK3: DESROSIERS | AL3: =SUMIF(B:B,AK3,AE:AE) -> 29 | AM3: =SUMIF(B:B,AK3,AF:AF) -> 62 | AN3: 17 | AO3: 3 | AQ3: 1 | AR3: MIOUSSE | AS3: 66 | AT3: 2024 | AV3: 44265 | AW3: HENAULT | AX3: 86 | AY3: =TODAY()-AV3 -> 1140 | BC3: 2022 | BD3: 2 | BE3: 44495 | BF3: PICARD | BG3: 45 | BI3: Étiquettes de lignes | BJ3: Nombre de POOLER | BK3: Min de Season | BL3: Max de PTS
A4: 1 | B4: MIOUSSE | C4: 1 | D4: 12 | E4: 4 | F4: 1 | G4: 7 | H4: 7 | I4: 6 | J4: 8 | K4: 12 | L4: 2 | M4: 2 | N4: 1 | O4: 2 | P4: 3 | Q4: 3 | R4: 4 | S4: 1 | T4: 5 | U4: 9 | V4: 9 | W4: 7 | X4: 1 | Y4: 1 | Z4: 6 | AA4: 2 | AB4: 2 | AC4: 346 | AD4: =AVERAGE(C4:AB4) -> 4.5384615 | AE4: =COUNTIF(C4:AB4,1) -> 6 | AF4: =COUNTIF(B4:AB4,"<=3") -> 13 | AH4: 1 | AI4: 25 | AK4: BEAUCHEMIN | AL4: =SUMIF(B:B,AK4,AE:AE) -> 23 | AM4: =SUMIF(B:B,AK4,AF:AF) -> 52 | AN4: 9 | AO4: 1 | AQ4: 2 | AR4: BEAUCHEMIN | AS4: 59 | AT4: 2022 | AV4: 44572 | AW4: ROBB | AX4: 65 | AY4: =TODAY()-AV4 -> 833 | BC4: 2022 | BD4: 3 | BE4: 44502 | BF4: ROBB | BG4: 46 | BI4: CHABOT | BJ4: 15 | BK4: 2022 | BL4: 57 | BO4: POOLER/WEEK | BP4: 1 | BQ4: 2 | BR4: 3 | BS4: 4 | BT4: 5 | BU4: 6 | BV4: 7 | BW4: 8 | BX4: 9 | BY4: 10 | BZ4: 11 | CA4: 12 | CB4: 13 | CC4: 14 | CD4: 15 | CE4: 16 | CF4: 17 | CG4: 18 | CH4: 19 | CI4: 20 | CJ4: 21 | CK4: 22 | CL4: 23 | CM4: 24 | CN4: 25 | CO4: 26
A5: 2 | B5: CHABOT | C5: 4 | D5: 8 | E5: 1 | F5: 8 | G5: 9 | H5: 11 | I5: 1 | J5: 3 | K5: 7 | L5: 5 | M5: 1 | N5: 11 | O5: 8 | P5: 5 | Q5: 1 | R5: 2 | S5: 4 | T5: 2 | U5: 7 | V5: 2 | W5: 12 | X5: 2 | Y5: 5 | Z5: 2 | AA5: 1 | AB5: 1 | AC5: 335 | AD5: =AVERAGE(C5:AB5) -> 4.7307692 | AE5: =COUNTIF(C5:AB5,1) -> 6 | AF5: =COUNTIF(B5:AB5,"<=3") -> 12 | AH5: 2 | AI5: 18 | AK5: CHABOT | AL5: =SUMIF(B:B,AK5,AE:AE) -> 22 | AM5: =SUMIF(B:B,AK5,AF:AF) -> 74 | AN5: 15 | AO5: 1 | AQ5: 3 | AR5: BEAUCHEMIN | AS5: 59 | AT5: 2019 | AV5: 44985 | AW5: DESROSIERS | AX5: 32 | AY5: =TODAY()-AV5 -> 420 | BC5: 2022 | BD5: 4 | BE5: 44509 | BF5: DESROSIERS | BG5: 40 | BI5: BEAUCHEMIN | BJ5: 11 | BK5: 2022 | BL5: 59 | BO5: MIOUSSE | BP5: 1 | BQ5: 12 | BR5: 4 | BS5: 1 | BT5: 7 | BU5: 7 | BV5: 6 | BW5: 8 | BX5: 12 | BY5: 2 | BZ5: 2 | CA5: 1 | CB5: 2 | CC5: 3 | CD5: 3 | CE5: 4
A6: 3 | B6: DIEGO | C6: 6 | D6: 3 | E6: 2 | F6: 9 | G6: 5 | H6: 2 | I6: 10 | J6: 1 | K6: 1 | L6: 4 | M6: 7 | N6: 3 | O6: 5 | P6: 6 | Q6: 6 | R6: 6 | S6: 8 | T6: 1 | U6: 2 | V6: 3 | W6: 6 | X6: 5 | Y6: 3 | Z6: 1 | AA6: 8 | AB6: 8 | AC6: 321 | AD6: =AVERAGE(C6:AB6) -> 4.6538462 | AE6: =COUNTIF(C6:AB6,1) -> 4 | AF6: =COUNTIF(B6:AB6,"<=3") -> 11 | AH6: 3 | AI6: 15 | AK6: PICARD | AL6: =SUMIF(B:B,AK6,AE:AE) -> 17 | AM6: =SUMIF(B:B,AK6,AF:AF) -> 47 | AN6: 10 | AQ6: 4 | AR6: DIEGO | AS6: 58 | AT6: 2024 | AV6: 45244 | AW6: LESSARD | AX6: 21 | AY6: =TODAY()-AV6 -> 161 | BC6: 2022 | BD6: 5 | BE6: 44516 | BF6: CHABOT | BG6: 45 | BI6: BLIER | BJ6: 9 | BK6: 2023 | BL6: 50 | BO6: BLIER | BP6: 5 | BQ6: 4 | BR6: 9 | BS6: 3 | BT6: 2 | BU6: 1 | BV6: 9 | BW6: 4 | BX6: 9 | BY6: 3 | BZ6: 3 | CA6: 7 | CB6: 1 | CC6: 2 | CD6: 5 | CE6: 3
A7: 4 | B7: BLIER | C7: 5 | D7: 4 | E7: 9 | F7: 3 | G7: 2 | H7: 1 | I7: 9 | J7: 4 | K7: 9 | L7: 3 | M7: 3 | N7: 7 | O7: 1 | P7: 2 | Q7: 5 | R7: 3 | S7: 3 | T7: 9 | U7: 10 | V7: 12 | W7: 10 | X7: 6 | Y7: 2 | Z7: 9 | AA7: 3 | AB7: 11 | AC7: 264 | AD7: =AVERAGE(C7:AB7) -> 5.5769231 | AE7: =COUNTIF(C7:AB7,1) -> 2 | AF7: =COUNTIF(B7:AB7,"<=3") -> 11 | AH7: 4 | AI7: 12 | AK7: FOR/CON | AL7: =VLOOKUP("CONSTANTIN",AK4:AO20,2,FALSE)+12 -> 17 | AM7: =VLOOKUP("CONSTANTIN",AK4:AO20,3,FALSE)+29 -> 46 | AN7: =VLOOKUP("CONSTANTIN",AK4:AO20,4,FALSE)+3 -> 5 | AQ7: 5 | AR7: MULTIPLE | AS7: 57 | AT7: xxx | AV7: 45279 | AW7: PICARD | AX7: 16 | AY7: =TODAY()-AV7 -> 126 | BC7: 2022 | BD7: 6 | BE7: 44523 | BF7: PICARD | BG7: 52 | BI7: PICARD | BJ7: 9 | BK7: 2022 | BL7: 52 | BO7: DIEGO | BP7: 6 | BQ7: 3 | BR7: 2 | BS7: 9 | BT7: 5 | BU7: 2 | BV7: 10 | BW7: 1 | BX7: 1 | BY7: 4 | BZ7: 7 | CA7: 3 | CB7: 5 | CC7: 6 | CD7: 6 | CE7: 6
A8: 5 | B8: BEAUCHEMIN | C8: 9 | D8: 1 | E8: 3 | F8: 10 | G8: 4 | H8: 4 | I8: 4 | J8: 10 | K8: 5 | L8: 7 | M8: 8 | N8: 5 | O8: 4 | P8: 1 | Q8: 7 | R8: 5 | S8: 6 | T8: 6 | U8: 8 | V8: 1 | W8: 3 | X8: 11 | Y8: 7 | Z8: 11 | AA8: 6 | AB8: 5 | AC8: 247 | AD8: =AVERAGE(C8:AB8) -> 5.8076923 | AE8: =COUNTIF(C8:AB8,1) -> 3 | AF8: =COUNTIF(B8:AB8,"<=3") -> 5 | AH8: 5 | AI8: 10 | AK8: BLIER | AL8: =SUMIF(B:B,AK8,AE:AE) -> 16 | AM8: =SUMIF(B:B,AK8,AF:AF) -> 45 | AN8: 14 | AO8: 1 | AV8: 45300 | AW8: BLIER | AX8: 13 | AY8: =TODAY()-AV8 -> 105 | BC8: 2022 | BD8: 7 | BE8: 44530 | BF8: PICARD | BG8: 40 | BI8: DESROSIERS | BJ8: 9 | BK8: 2022 | BL8: 56 | BO8: CHABOT | BP8: 4 | BQ8: 8 | BR8: 1 | BS8: 8 | BT8: 9 | BU8: 11 | BV8: 1 | BW8: 3 | BX8: 7 | BY8: 5 | BZ8: 1 | CA8: 11 | CB8: 8 | CC8: 5 | CD8: 1 | CE8: 2
A9: 6 | B9: CONSTANTIN | C9: 8 | D9: 6 | E9: 5 | F9: 2 | G9: 3 | H9: 8 | I9: 2 | J9: 11 | K9: 2 | L9: 10 | M9: 6 | N9: 4 | O9: 9 | P9: 8 | Q9: 4 | R9: 8 | S9: 2 | T9: 4 | U9: 4 | V9: 7 | W9: 1 | X9: 10 | Y9: 11 | Z9: 4 | AA9: 4 | AB9: 6 | AC9: 244 | AD9: =AVERAGE(C9:AB9) -> 5.7307692 | AE9: =COUNTIF(C9:AB9,1) -> 1 | AF9: =COUNTIF(B9:AB9,"<=3") -> 6 | AH9: 6 | AI9: 8 | AK9: FORCIER | AL9: =SUMIF(B:B,AK9,AE:AE) -> 12 | AM9: =SUMIF(B:B,AK9,AF:AF) -> 29 | AN9: 3 | AR9: Most Wins in Sea | AV9: 45349 | AW9: MOROTTI | AX9: 7 | AY9: =TODAY()-AV9 -> 56 | BC9: 2022 | BD9: 8 | BE9: 44537 | BF9: CONSTANTIN | BG9: 48 | BI9: MIOUSSE | BJ9: 7 | BK9: 2023 | BL9: 66 | BO9: BEAUCHEMIN | BP9: 9 | BQ9: 1 | BR9: 3 | BS9: 10 | BT9: 4 | BU9: 4 | BV9: 4 | BW9: 10 | BX9: 5 | BY9: 7 | BZ9: 8 | CA9: 5 | CB9: 4 | CC9: 1 | CD9: 7 | CE9: 5
A10: 7 | B10: MOROTTI | C10: 3 | D10: 5 | E10: 11 | F10: 6 | G10: 12 | H10: 3 | I10: 8 | J10: 9 | K10: 6 | L10: 11 | M10: 11 | N10: 10 | O10: 11 | P10: 10 | Q10: 2 | R10: 1 | S10: 9 | T10: 7 | U10: 1 | V10: 5 | W10: 2 | X10: 4 | Y10: 4 | Z10: 3 | AA10: 5 | AB10: 7 | AC10: 223 | AD10: =AVERAGE(C10:AB10) -> 6.3846154 | AE10: =COUNTIF(C10:AB10,1) -> 2 | AF10: =COUNTIF(B10:AB10,"<=3") -> 7 | AH10: 7 | AI10: 6 | AK10: MIOUSSE | AL10: =SUMIF(B:B,AK10,AE:AE) -> 11 | AM10: =SUMIF(B:B,AK10,AF:AF) -> 32 | AN10: 8 | AO10: 1 | AQ10: 1 | AR10: DESROSIERS | AS10: 8 | AT10: 2020 | AV10: 45357 | AW10: BEAUCHEMIN | AX10: 6 | AY10: =TODAY()-AV10 -> 48 | BC10: 2022 | BD10: 9 | BE10: 44544 | BF10: CONSTANTIN | BG10: 37 | BI10: DIEGO | BJ10: 7 | BK10: 2022 | BL10: 58 | BO10: LESSARD | BP10: 2 | BQ10: 2 | BR10: 6 | BS10: 12 | BT10: 1 | BU10: 9 | BV10: 5 | BW10: 2 | BX10: 10 | BY10: 9 | BZ10: 10 | CA10: 2 | CB10: 3 | CC10: 4 | CD10: 9 | CE10: 10
A11: 8 | B11: LESSARD | C11: 2 | D11: 2 | E11: 6 | F11: 12 | G11: 1 | H11: 9 | I11: 5 | J11: 2 | K11: 10 | L11: 9 | M11: 10 | N11: 2 | O11: 3 | P11: 4 | Q11: 9 | R11: 10 | S11: 11 | T11: 12 | U11: 5 | V11: 4 | W11: 4 | X11: 7 | Y11: 8 | Z11: 8 | AA11: 12 | AB11: 4 | AC11: 213 | AD11: =AVERAGE(C11:AB11) -> 6.5769231 | AE11: =COUNTIF(C11:AB11,1) -> 1 | AF11: =COUNTIF(B11:AB11,"<=3") -> 6 | AH11: 8 | AI11: 4 | AK11: DIEGO | AL11: =SUMIF(B:B,AK11,AE:AE) -> 9 | AM11: =SUMIF(B:B,AK11,AF:AF) -> 41 | AN11: 19 | AQ11: 2 | AR11: DESROSIERS | AS11: 7 | AT11: 2023 | AV11: 45363 | AW11: CONSTANTIN | AX11: 5 | AY11: =TODAY()-AV11 -> 42 | BC11: 2022 | BD11: 10 | BE11: 44551 | BF11: CONSTANTIN | BG11: 36 | BI11: CONSTANTIN | BJ11: 5 | BK11: 2022 | BL11: 48 | BO11: CONSTANTIN | BP11: 8 | BQ11: 6 | BR11: 5 | BS11: 2 | BT11: 3 | BU11: 8 | BV11: 2 | BW11: 11 | BX11: 2 | BY11: 10 | BZ11: 6 | CA11: 4 | CB11: 9 | CC11: 8 | CD11: 4 | CE11: 8
A12: 9 | B12: PICARD | C12: 7 | D12: 7 | E12: 7 | F12: 4 | G12: 8 | H12: 5 | I12: 7 | J12: 6 | K12: 4 | L12: 1 | M12: 4 | N12: 12 | O12: 6 | P12: 7 | Q12: 10 | R12: 12 | S12: 5 | T12: 3 | U12: 3 | V12: 6 | W12: 11 | X12: 3 | Y12: 6 | Z12: 10 | AA12: 10 | AB12: 3 | AC12: 210 | AD12: =AVERAGE(C12:AB12) -> 6.4230769 | AE12: =COUNTIF(C12:AB12,1) -> 1 | AF12: =COUNTIF(B12:AB12,"<=3") -> 5 | AH12: 9 | AI12: 2 | AK12: HENAULT | AL12: =SUMIF(B:B,AK12,AE:AE) -> 9 | AM12: =SUMIF(B:B,AK12,AF:AF) -> 29 | AN12: 11 | AQ12: 3 | AR12: CHABOT | AS12: 7 | AT12: 2023 | AV12: 45377 | AW12: MIOUSSE | AX12: 3 | AY12: =TODAY()-AV12 -> 28 | BC12: 2022 | BD12: 11 | BE12: 44565 | BF12: CHABOT | BG12: 43 | BI12: MOROTTI | BJ12: 2 | BK12: 2024 | BL12: 53 | BO12: PICARD | BP12: 7 | BQ12: 7 | BR12: 7 | BS12: 4 | BT12: 8 | BU12: 5 | BV12: 7 | BW12: 6 | BX12: 4 | BY12: 1 | BZ12: 4 | CA12: 12 | CB12: 6 | CC12: 7 | CD12: 10 | CE12: 12
A13: 10 | B13: HENAULT | C13: 11 | D13: 9 | E13: 8 | F13: 5 | G13: 11 | H13: 6 | I13: 3 | J13: 5 | K13: 8 | L13: 6 | M13: 9 | N13: 6 | O13: 10 | P13: 9 | Q13: 11 | R13: 9 | S13: 12 | T13: 8 | U13: 6 | V13: 10 | W13: 8 | X13: 8 | Y13: 9 | Z13: 7 | AA13: 9 | AB13: 9 | AC13: 109 | AD13: =AVERAGE(C13:AB13) -> 8.1538462 | AE13: =COUNTIF(C13:AB13,1) -> 0 | AF13: =COUNTIF(B13:AB13,"<=3") -> 1 | AH13: 10 | AI13: 1 | AK13: MOROTTI | AL13: =SUMIF(B:B,AK13,AE:AE) -> 7 | AM13: =SUMIF(B:B,AK13,AF:AF) -> 30 | AN13: 14 | AQ13: 4 | AR13: PICARD | AS13: 7 | AT13: 2022 | AV13: 45384 | AW13: DIEGO | AX13: 2 | AY13: =TODAY()-AV13 -> 21 | BC13: 2022 | BD13: 12 | BE13: 44572 | BF13: ROBB | BG13: 42 | BI13: ROBB | BJ13: 2 | BK13: 2022 | BL13: 46 | BO13: MOROTTI | BP13: 3 | BQ13: 5 | BR13: 11 | BS13: 6 | BT13: 12 | BU13: 3 | BV13: 8 | BW13: 9 | BX13: 6 | BY13: 11 | BZ13: 11 | CA13: 10 | CB13: 11 | CC13: 10 | CD13: 2 | CE13: 1
A14: 11 | B14: ROBB | C14: 10 | D14: 11 | E14: 12 | F14: 7 | G14: 6 | H14: 10 | I14: 11 | J14: 7 | K14: 3 | L14: 8 | M14: 12 | N14: 8 | O14: 7 | P14: 12 | Q14: 8 | R14: 7 | S14: 10 | T14: 11 | U14: 11 | V14: 8 | W14: 5 | X14: 12 | Y14: 10 | Z14: 12 | AA14: 11 | AB14: 12 | AC14: 77 | AD14: =AVERAGE(C14:AB14) -> 9.2692308 | AE14: =COUNTIF(C14:AB14,1) -> 0 | AF14: =COUNTIF(B14:AB14,"<=3") -> 1 | AK14: DAV/ROB | AL14: =VLOOKUP("ROBB",AK2:AO18,2,FALSE) -> 5 | AM14: =VLOOKUP("robb",AK3:AN18,3,FALSE)+5 -> 23 | AN14: =VLOOKUP("robb",AK3:AN18,4,FALSE)+2 -> 21 | AQ14: 5 | AR14: MULTIPLE | AS14: 6 | AT14: X | AV14: 45398 | AW14: CHABOT | AX14: 0 | AY14: =TODAY()-AV14 -> 7 | BC14: 2022 | BD14: 13 | BE14: 44579 | BF14: CHABOT | BG14: 40 | BI14: LESSARD | BJ14: 1 | BK14: 2024 | BL14: 44 | BO14: HENAULT | BP14: 11 | BQ14: 9 | BR14: 8 | BS14: 5 | BT14: 11 | BU14: 6 | BV14: 3 | BW14: 5 | BX14: 8 | BY14: 6 | BZ14: 9 | CA14: 6 | CB14: 10 | CC14: 9 | CD14: 11 | CE14: 9
A15: 12 | B15: DESROSIERS | C15: 12 | D15: 10 | E15: 10 | F15: 11 | G15: 10 | H15: 12 | I15: 12 | J15: 12 | K15: 11 | L15: 12 | M15: 5 | N15: 9 | O15: 12 | P15: 11 | Q15: 12 | R15: 11 | S15: 7 | T15: 10 | U15: 12 | V15: 11 | W15: 9 | X15: 9 | Y15: 12 | Z15: 5 | AA15: 7 | AB15: 10 | AC15: 43 | AD15: =AVERAGE(C15:AB15) -> 10.153846 | AE15: =COUNTIF(C15:AB15,1) -> 0 | AF15: =COUNTIF(B15:AB15,"<=3") -> 0 | AK15: ROBB | AL15: =SUMIF(B:B,AK15,AE:AE) -> 5 | AM15: =SUMIF(B:B,AK15,AF:AF) -> 18 | AN15: 19 | BC15: 2022 | BD15: 14 | BE15: 44586 | BF15: PICARD | BG15: 49 | BI15: (vide) | BO15: ROBB | BP15: 10 | BQ15: 11 | BR15: 12 | BS15: 7 | BT15: 6 | BU15: 10 | BV15: 11 | BW15: 7 | BX15: 3 | BY15: 8 | BZ15: 12 | CA15: 8 | CB15: 7 | CC15: 12 | CD15: 8 | CE15: 7
AK16: CONSTANTIN | AL16: =SUMIF(B:B,AK16,AE:AE) -> 5 | AM16: =SUMIF(B:B,AK16,AF:AF) -> 17 | AN16: 2 | AR16: Most Podiums in Sea | AW16: Most Weeks Between Ws | BC16: 2022 | BD16: 15 | BE16: 44593 | BF16: DIEGO | BG16: 45 | BI16: Total général | BJ16: 77 | BK16: 2022 | BL16: 66 | BO16: DESROSIERS | BP16: 12 | BQ16: 10 | BR16: 10 | BS16: 11 | BT16: 10 | BU16: 12 | BV16: 12 | BW16: 12 | BX16: 11 | BY16: 12 | BZ16: 5 | CA16: 9 | CB16: 12 | CC16: 11 | CD16: 12 | CE16: 11
AK17: LESSARD | AL17: =SUMIF(B:B,AK17,AE:AE) -> 4 | AM17: =SUMIF(B:B,AK17,AF:AF) -> 26 | AN17: 25 | AQ17: 1 | AR17: DESROSIERS | AS17: 17 | AT17: 2020 | AW17: DIEGO | AX17: 87 | AY17: 18-21 | BC17: 2022 | BD17: 16 | BE17: 44607 | BF17: BEAUCHEMIN | BG17: 59
AK18: DAVID | AL18: =SUMIF(B:B,AK18,AE:AE) -> 0 | AM18: =SUMIF(B:B,AK18,AF:AF) -> 5 | AN18: 2 | AQ18: 2 | AR18: CHABOT | AS18: 15 | AT18: 2023 | AW18: MOROTTI | AX18: 66 | AY18: 21-24 | BC18: 2022 | BD18: 17 | BE18: 44614 | BF18: PICARD | BG18: 52
AQ19: 3 | AR19: CHABOT | AS19: 15 | AT19: 2022 | AW19: LESSARD | AX19: 60 | AY19: 18-21 | BC19: 2022 | BD19: 18 | BE19: 44621 | BF19: BEAUCHEMIN | BG19: 45
AQ20: 4 | AR20: DESROSIERS | AS20: 14 | AT20: 2019 | AW20: MOROTTI | AX20: 55 | AY20: 18-20 | BC20: 2022 | BD20: 19 | BE20: 44628 | BF20: PICARD | BG20: 45
AQ21: 5 | AR21: BEAUCHEMIN | AS21: 14 | AT21: 2018 | AW21: CONSTANTIN | AX21: 50 | AY21: 22-24 | BC21: 2022 | BD21: 20 | BE21: 44635 | BF21: CHABOT | BG21: 45
AW22: PICARD | AX22: 24 | AY22: 18-19 | BC22: 2022 | BD22: 21 | BE22: 44642 | BF22: CONSTANTIN | BG22: 40
B23: WEEK 2 WEEK CUP 2023 | AR23: Most Wins in a Row | AW23: CHABOT | AX23: 19 | AY23: 18-19 | BC23: 2022 | BD23: 22 | BE23: 44649 | BF23: PICARD | BG23: 51
B24: POOLER/WEEK | C24: 1 | D24: 2 | E24: 3 | F24: 4 | G24: 5 | H24: 6 | I24: 7 | J24: 8 | K24: 9 | L24: 10 | M24: 11 | N24: 12 | O24: 13 | P24: 14 | Q24: 15 | R24: 16 | S24: 17 | T24: 18 | U24: 19 | V24: 20 | W24: 21 | X24: 22 | Y24: 23 | Z24: 24 | AA24: 25 | AC24: TOTAL | AD24: AVG | AE24: W | AF24: PD | AQ24: 1 | AR24: BLIER | AS24: 3 | AT24: 2023 | AW24: DESROSIERS | AX24: 11 | AY24: 18-19 | BC24: 2022 | BD24: 23 | BE24: 44656 | BF24: CHABOT | BG24: 47
A25: 1 | B25: DESROSIERS | C25: 1 | D25: 8 | E25: 1 | F25: 6 | G25: 1 | H25: 12 | I25: 7 | J25: 1 | K25: 6 | L25: 1 | M25: 9 | N25: 3 | O25: 1 | P25: 2 | Q25: 5 | R25: 2 | S25: 3 | T25: 6 | U25: 1 | V25: 2 | W25: 4 | X25: 2 | Y25: 6 | Z25: 7 | AA25: 7 | AC25: 355 | AD25: =AVERAGE(C25:AB25) -> 4.16 | AE25: =COUNTIF(C25:AB25,1) -> 7 | AF25: =COUNTIF(B25:AB25,"<=3") -> 13 | AQ25: 2 | AR25: CONSTANTIN | AS25: 3 | AT25: 2022 | AW25: BEAUCHEMIN | AX25: 10 | AY25: 2018 | BC25: 2022 | BD25: 24 | BE25: 44663 | BF25: BEAUCHEMIN | BG25: 51
A26: 2 | B26: BLIER | C26: 2 | D26: 9 | E26: 5 | F26: 1 | G26: 5 | H26: 4 | I26: 5 | J26: 3 | K26: 2 | L26: 5 | M26: 1 | N26: 1 | O26: 10 | P26: 6 | Q26: 11 | R26: 1 | S26: 11 | T26: 4 | U26: 6 | V26: 1 | W26: 1 | X26: 1 | Y26: 4 | Z26: 5 | AA26: 12 | AC26: 331 | AD26: =AVERAGE(C26:AB26) -> 4.64 | AE26: =COUNTIF(C26:AB26,1) -> 7 | AF26: =COUNTIF(B26:AB26,"<=3") -> 10 | AQ26: 3 | AR26: BLIER | AS26: 3 | AT26: 2021 | AW26: CHABOT | AX26: 9 | AY26: 2018 | BC26: 2022 | BD26: 25 | BE26: 44670 | BF26: BEAUCHEMIN | BG26: 59
A27: 3 | B27: CHABOT | C27: 6 | D27: 1 | E27: 3 | F27: 12 | G27: 11 | H27: 1 | I27: 3 | J27: 2 | K27: 4 | L27: 2 | M27: 10 | N27: 2 | O27: 3 | P27: 1 | Q27: 2 | R27: 3 | S27: 9 | T27: 2 | U27: 11 | V27: 3 | W27: 7 | X27: 9 | Y27: 2 | Z27: 6 | AA27: 3 | AC27: 312 | AD27: =AVERAGE(C27:AB27) -> 4.72 | AE27: =COUNTIF(C27:AB27,1) -> 3 | AF27: =COUNTIF(B27:AB27,"<=3") -> 15 | AQ27: 4 | AR27: MULTIPLE | AS27: 2 | AT27: X | AW27: DESROSIERS | AX27: 3 | AY27: 2018 | BC27: 2022 | BD27: 26 | BE27: 44677 | BF27: DESROSIERS | BG27: 48
A28: 4 | B28: DIEGO | C28: 11 | D28: 11 | E28: 6 | F28: 2 | G28: 2 | H28: 6 | I28: 2 | J28: 12 | K28: 1 | L28: 7 | M28: 3 | N28: 4 | O28: 6 | P28: 3 | Q28: 1 | R28: 4 | S28: 6 | T28: 3 | U28: 7 | V28: 11 | W28: 3 | X28: 8 | Y28: 5 | Z28: 2 | AA28: 2 | AC28: 282 | AD28: =AVERAGE(C28:AB28) -> 5.12 | AE28: =COUNTIF(C28:AB28,1) -> 2 | AF28: =COUNTIF(B28:AB28,"<=3") -> 11 | AW28: BEAUCHEMIN | AX28: 1 | AY28: 2018 | BC28: 2023 | BD28: 1 | BE28: 44852 | BF28: DESROSIERS | BG28: 53
A29: 5 | B29: BEAUCHEMIN | C29: 8 | D29: 5 | E29: 2 | F29: 8 | G29: 3 | H29: 7 | I29: 4 | J29: 6 | K29: 5 | L29: 9 | M29: 7 | N29: 5 | O29: 4 | P29: 7 | Q29: 8 | R29: 10 | S29: 1 | T29: 1 | U29: 12 | V29: 4 | W29: 9 | X29: 3 | Y29: 3 | Z29: 1 | AA29: 1 | AC29: 272 | AD29: =AVERAGE(C29:AB29) -> 5.32 | AE29: =COUNTIF(C29:AB29,1) -> 4 | AF29: =COUNTIF(B29:AB29,"<=3") -> 8 | AR29: Most Pod in a Row | BC29: 2023 | BD29: 2 | BE29: 44859 | BF29: CHABOT | BG29: 42
A30: 6 | B30: PICARD | C30: 3 | D30: 12 | E30: 10 | F30: 3 | G30: 6 | H30: 2 | I30: 1 | J30: 5 | K30: 12 | L30: 4 | M30: 2 | N30: 11 | O30: 5 | P30: 9 | Q30: 3 | R30: 9 | S30: 7 | T30: 10 | U30: 8 | V30: 7 | W30: 2 | X30: 6 | Y30: 9 | Z30: 4 | AA30: 6 | AC30: 216 | AD30: =AVERAGE(C30:AB30) -> 6.24 | AE30: =COUNTIF(C30:AB30,1) -> 1 | AF30: =COUNTIF(B30:AB30,"<=3") -> 7 | AQ30: 1 | AR30: CHABOT | AS30: 7 | AT30: 2022 | BC30: 2023 | BD30: 3 | BE30: 44866 | BF30: DESROSIERS | BG30: 43
A31: 7 | B31: MIOUSSE | C31: 4 | D31: 7 | E31: 4 | F31: 9 | G31: 4 | H31: 5 | I31: 10 | J31: 4 | K31: 7 | L31: 10 | M31: 8 | N31: 12 | O31: 2 | P31: 10 | Q31: 6 | R31: 8 | S31: 10 | T31: 5 | U31: 2 | V31: 5 | W31: 8 | X31: 10 | Y31: 1 | Z31: 9 | AA31: 5 | AC31: 190 | AD31: =AVERAGE(C31:AB31) -> 6.6 | AE31: =COUNTIF(C31:AB31,1) -> 1 | AF31: =COUNTIF(B31:AB31,"<=3") -> 3 | AQ31: 2 | AR31: MIOUSSE | AS31: 6 | AT31: 2024 | BC31: 2023 | BD31: 4 | BE31: 44873 | BF31: BLIER | BG31: 50
A32: 8 | B32: CONSTANTIN | C32: 10 | D32: 2 | E32: 7 | F32: 4 | G32: 8 | H32: 9 | I32: 12 | J32: 9 | K32: 10 | L32: 3 | M32: 4 | N32: 6 | O32: 11 | P32: 5 | Q32: 7 | R32: 5 | S32: 8 | T32: 9 | U32: 9 | V32: 8 | W32: 5 | X32: 7 | Y32: 10 | Z32: 8 | AA32: 4 | AC32: 152 | AD32: =AVERAGE(C32:AB32) -> 7.2 | AE32: =COUNTIF(C32:AB32,1) -> 0 | AF32: =COUNTIF(B32:AB32,"<=3") -> 2 | AQ32: 3 | AR32: MULTIPLE | AS32: 5 | AT32: X | BC32: 2023 | BD32: 5 | BE32: 44880 | BF32: DESROSIERS | BG32: 46
A33: 9 | B33: LESSARD | C33: 9 | D33: 4 | E33: 10 | F33: 7 | G33: 9 | H33: 3 | I33: 9 | J33: 11 | K33: 3 | L33: 8 | M33: 5 | N33: 7 | O33: 8 | P33: 12 | Q33: 12 | R33: 12 | S33: 4 | T33: 8 | U33: 3 | V33: 9 | W33: 12 | X33: 4 | Y33: 8 | Z33: 12 | AA33: 8 | AC33: 137 | AD33: =AVERAGE(C33:AB33) -> 7.88 | AE33: =COUNTIF(C33:AB33,1) -> 0 | AF33: =COUNTIF(B33:AB33,"<=3") -> 3 | AQ33: 3 | BC33: 2023 | BD33: 6 | BE33: 44887 | BF33: CHABOT | BG33: 49
A34: 10 | B34: MOROTTI | C34: 7 | D34: 3 | E34: 8 | F34: 5 | G34: 7 | H34: 11 | I34: 11 | J34: 7 | K34: 8 | L34: 6 | M34: 11 | N34: 8 | O34: 12 | P34: 4 | Q34: 9 | R34: 7 | S34: 5 | T34: 7 | U34: 10 | V34: 12 | W34: 6 | X34: 5 | Y34: 11 | Z34: 11 | AA34: 9 | AC34: 120 | AD34: =AVERAGE(C34:AB34) -> 8 | AE34: =COUNTIF(C34:AB34,1) -> 0 | AF34: =COUNTIF(B34:AB34,"<=3") -> 1 | AR34: Best AVG | BC34: 2023 | BD34: 7 | BE34: 44894 | BF34: PICARD | BG34: 46
A35: 11 | B35: HENAULT | C35: 12 | D35: 6 | E35: 11 | F35: 11 | G35: 12 | H35: 8 | I35: 6 | J35: 8 | K35: 9 | L35: 11 | M35: 12 | N35: 9 | O35: 9 | P35: 11 | Q35: 4 | R35: 6 | S35: 12 | T35: 11 | U35: 4 | V35: 10 | W35: 10 | X35: 12 | Y35: 7 | Z35: 3 | AA35: 10 | AC35: 86 | AD35: =AVERAGE(C35:AB35) -> 8.96 | AE35: =COUNTIF(C35:AB35,1) -> 0 | AF35: =COUNTIF(B35:AB35,"<=3") -> 1 | AQ35: 1 | AR35: DESROSIERS | AS35: 3.04 | AT35: 2020 | BC35: 2023 | BD35: 8 | BE35: 44901 | BF35: DESROSIERS | BG35: 49
A36: 12 | B36: ROBB | C36: 5 | D36: 10 | E36: 12 | F36: 10 | G36: 10 | H36: 10 | I36: 8 | J36: 10 | K36: 11 | L36: 12 | M36: 6 | N36: 10 | O36: 7 | P36: 8 | Q36: 10 | R36: 11 | S36: 2 | T36: 12 | U36: 5 | V36: 6 | W36: 11 | X36: 11 | Y36: 12 | Z36: 10 | AA36: 11 | AC36: 76 | AD36: =AVERAGE(C36:AB36) -> 9.2 | AE36: =COUNTIF(C36:AB36,1) -> 0 | AF36: =COUNTIF(B36:AB36,"<=3") -> 1 | AQ36: 2 | AR36: BEAUCHEMIN | AS36: 3.77 | AT36: 2018 | BC36: 2023 | BD36: 9 | BE36: 44908 | BF36: DIEGO | BG36: 46
AQ37: 3 | AR37: DESROSIERS | AS37: 4.16 | AT37: 2023 | BC37: 2023 | BD37: 10 | BE37: 44915 | BF37: DESROSIERS | BG37: 56
AQ38: 4 | AR38: DESROSIERS | AS38: 4.23 | AT38: 2019 | BC38: 2023 | BD38: 11 | BE38: 44922 | BF38: BLIER | BG38: 34
B39: WEEK 2 WEEK CUP 2022 | AQ39: 5 | AR39: CHABOT | AS39: 4.27 | AT39: 2022 | BC39: 2023 | BD39: 12 | BE39: 44929 | BF39: BLIER | BG39: 41
B40: POOLER/WEEK | C40: 1 | D40: 2 | E40: 3 | F40: 4 | G40: 5 | H40: 6 | I40: 7 | J40: 8 | K40: 9 | L40: 10 | M40: 11 | N40: 12 | O40: 13 | P40: 14 | Q40: 15 | R40: 16 | S40: 17 | T40: 18 | U40: 19 | V40: 20 | W40: 21 | X40: 22 | Y40: 23 | Z40: 24 | AA40: 25 | AB40: 26 | AC40: TOTAL | AD40: AVG | AE40: W | AF40: PD | BC40: 2023 | BD40: 13 | BE40: 44936 | BF40: DESROSIERS | BG40: 49
...

Sheet 24
A1: 2023 | B1: DESROSIERS | D1: CHABOT | F1: BLIER | H1: BEAUCHEMIN | J1: PICARD | L1: MIOUSSE | N1: CONSTANTIN | P1: LESSARD | R1: ROBB | T1: MOROTTI | V1: HENAULT | X1: DIEGO | AB1: F | AC1: D | AD1: G | AE1: T
A2: 1 | B2: THOMPSON | C2: 56 | D2: TARASENKO | E2: 55 | F2: TOFFOLI | G2: 55 | H2: PASTRNAK | I2: 110 | J2: MARNER | K2: 85 | L2: TKACHUK M. | M2: 88 | N2: ROBERTSON | O2: 80 | P2: RANTANEN | Q2: 104 | R2: MACKINNON | S2: 140 | T2: DRAISAITL | U2: 106 | V2: BEDARD | W2: 61 | X2: MCDAVID | Y2: 132 | AA2: DESROSIERS | AB2: =SUMPRODUCT(LARGE(C2:C13,{1;2;3;4;5;6;7;8})) -> 447 | AC2: =SUMPRODUCT(LARGE(C14:C18,{1;2;3})) -> 110 | AD2: =LARGE(C19:C20,1) -> 93 | AE2: =C21 -> 52 | AL2: LESSY - Franchise Record | AQ2: Miousse - Sharpool Record
A3: 2 | B3: SUZUKI | C3: 77 | D3: PANARIN | E3: 120 | F3: KUCHEROV | G3: 144 | H3: STUTZLE | I3: 70 | J3: MILLER JT. | K3: 103 | L3: MATTHEWS | M3: 107 | N3: PAVELSKI | O3: 67 | P3: TAVARES | Q3: 65 | R3: HINTZ | S3: 65 | T3: POINT | U3: 90 | V3: GAUDREAU | W3: 60 | X3: HUGHES J. | Y3: 74 | AA3: CHABOT | AB3: =SUMPRODUCT(LARGE(E2:E13,{1;2;3;4;5;6;7;8})) -> 640 | AC3: =SUMPRODUCT(LARGE(E14:E18,{1;2;3})) -> 182 | AD3: =LARGE(E19:E20,1) -> 83 | AE3: =E21 -> 98 | AL3: Most points by a Forward Group | AQ3: Most points in a Season by a Defence Group
A4: 3 | B4: KOVALENKO | C4: 0 | D4: STAMKOS | E4: 81 | F4: PETTERSSON | G4: 89 | H4: HISCHIER | I4: 67 | J4: KAPRIZOV | K4: 96 | L4: GUENTZEL | M4: 77 | N4: BRATT | O4: 83 | P4: NELSON | Q4: 69 | R4: TROCHECK | S4: 77 | T4: TKACHUK B. | U4: 74 | V4: EICHEL | W4: 68 | X4: NYLANDER | Y4: 98 | AA4: BLIER | AB4: =SUMPRODUCT(LARGE(G2:G13,{1;2;3;4;5;6;7;8})) -> 636 | AC4: =SUMPRODUCT(LARGE(G14:G18,{1;2;3})) -> 142 | AD4: =LARGE(G19:G20,1) -> 60 | AE4: =G21 -> 113 | AL4: NEW - 2024 | AN4: OLD - 2022 | AQ4: NEW - 2024 | AS4: BEAUCH - OLD - 2023
A5: 4 | B5: KELLER | C5: 76 | D5: TUCH | E5: 59 | F5: CROSBY | G5: 94 | H5: BARKOV | I5: 80 | J5: SCHEIFELE | K5: 72 | L5: AHO | M5: 89 | N5: HORVAT | O5: 68 | P5: KANE P. | Q5: 47 | R5: BOESER | S5: 73 | T5: MALKIN | U5: 67 | V5: FORSBERG | W5: 94 | X5: CONNOR | Y5: 61 | AA5: BEAUCHEMIN | AB5: =SUMPRODUCT(LARGE(I2:I13,{1;2;3;4;5;6;7;8})) -> 599 | AC5: =SUMPRODUCT(LARGE(I14:I18,{1;2;3})) -> 167 | AD5: =LARGE(I19:I20,1) -> 91 | AE5: =I21 -> 81 | AL5: RANTANEN | AM5: 103 | AN5: PERRON | AO5: 57 | AQ5: HUGHES Q. | AR5: 92 | AS5: WERENSKI | AT5: 8
A6: 5 | B6: COZENS | C6: 47 | D6: KYROU | E6: 67 | F6: OVECHKIN | G6: 65 | H6: LARKIN | I6: 69 | J6: ZEGRAS | K6: 15 | L6: KEMPE | M6: 75 | N6: HUBERDEAU | O6: 52 | P6: SVECHNIKOV | Q6: 52 | R6: BUNTING | S6: 55 | T6: ZUCCARELLO | U6: 63 | V6: JOHNSON K. | W6: 16 | X6: GIROUX | Y6: 64 | AA6: PICARD | AB6: =SUMPRODUCT(LARGE(K2:K13,{1;2;3;4;5;6;7;8})) -> 576 | AC6: =SUMPRODUCT(LARGE(K14:K18,{1;2;3})) -> 152 | AD6: =LARGE(K19:K20,1) -> 88 | AE6: =K21 -> 102 | AG6: BEDARD | AH6: 69.5 | AL6: TAVARES | AM6: 64 | AN6: O'REILLY | AO6: 58 | AQ6: RIELLY | AR6: 58 | AS6: SEIDER | AT6: 42
A7: 6 | B7: MACCELLI | C7: 57 | D7: NECAS | E7: 53 | F7: VERHAEGHE | G7: 72 | H7: FIALA | I7: 73 | J7: LINDHOLM E. | K7: 44 | L7: BENIERS | M7: 37 | N7: WHEELER | O7: 21 | P7: KUZNETSOV | Q7: 24 | R7: KAKKO | S7: 19 | T7: DUBOIS | U7: 40 | V7: LUNDELL | W7: 35 | X7: MARCHAND | Y7: 67 | AA7: MIOUSSE | AB7: =SUMPRODUCT(LARGE(M2:M13,{1;2;3;4;5;6;7;8})) -> 644 | AC7: =SUMPRODUCT(LARGE(M14:M18,{1;2;3})) -> 193 | AD7: =LARGE(M19:M20,1) -> 88 | AE7: =M21 -> 111 | AG7: matchs | AH7: 66 | AL7: NELSON | AM7: 69 | AN7: TAVARES | AO7: 76 | AQ7: KLINGBERG | AR7: 5 | AS7: DOBSON | AT7: 49
A8: 7 | B8: COOLEY | C8: 44 | D8: THOMAS | E8: 86 | F8: BUCHNEVICH | G8: 63 | H8: CAUFIELD | I8: 65 | J8: KONECNY | K8: 68 | L8: BJORKSTRAND | M8: 59 | N8: KARLSSON W. | O8: 60 | P8: MCTAVICH | Q8: 42 | R8: TERAVAINEN | S8: 53 | T8: MARCHESSAULT | U8: 69 | V8: NORRIS | W8: 30 | X8: MEIER | Y8: 52 | AA8: CONSTANTIN | AB8: =SUMPRODUCT(LARGE(O2:O13,{1;2;3;4;5;6;7;8})) -> 562 | AC8: =SUMPRODUCT(LARGE(O14:O18,{1;2;3})) -> 175 | AD8: =LARGE(O19:O20,1) -> 98 | AE8: =O21 -> 98 | AG8: pts | AH8: =W2 -> 61 | AL8: KANE P. | AM8: 47 | AN8: SVECHNIKOV | AO8: 69 | AQ8: BURNS | AR8: 43 | AS8: KARLSSON E. | AT8: 101
A9: 8 | B9: FANTILLI | C9: 27 | D9: BOLDY | E9: 69 | F9: TERRY | G9: 54 | H9: MERCER | I9: 33 | J9: KANE E. | K9: 44 | L9: EHLERS | M9: 61 | N9: JOHNSTON | O9: 65 | P9: BERTUZZI | Q9: 43 | R9: BYFIELD | S9: 55 | T9: BARZAL | U9: 80 | V9: NUGENT-HOPKINS | W9: 67 | X9: RAYMOND | Y9: 72 | AA9: LESSARD | AB9: =SUMPRODUCT(LARGE(Q2:Q13,{1;2;3;4;5;6;7;8})) -> 555 | AC9: =SUMPRODUCT(LARGE(Q14:Q18,{1;2;3})) -> 143 | AD9: =LARGE(Q19:Q20,1) -> 72 | AE9: =Q21 -> 109 | AG9: pts/gp | AH9: =AH8/AH7 -> 0.92424242 | AL9: SVECHNIKOV | AM9: 52 | AN9: NYLANDER | AO9: 80 | AQ9: SEVERSON | AR9: 28 | AS9: DURZI | AT9: 38
A10: 9 | B10: CARLSSON | C10: 29 | D10: LAINE | E10: 9 | F10: SEGUIN | G10: 52 | H10: KNIES | I10: 35 | J10: NICHUSHKIN | K10: 53 | L10: HYMAN | M10: 77 | N10: HAGEL | O10: 75 | P10: DEBRINCAT | Q10: 67 | R10: KUZMENKO | S10: 46 | T10: RUST | U10: 56 | V10: VILARDI | W10: 36 | X10: DACH | Y10: 2 | AA10: ROBB | AB10: =SUMPRODUCT(LARGE(S2:S13,{1;2;3;4;5;6;7;8})) -> 587 | AC10: =SUMPRODUCT(LARGE(S14:S18,{1;2;3})) -> 109 | AD10: =LARGE(S19:S20,1) -> 22 | AE10: =S21 -> 47 | AG10: Matchs potentiels | AH10: =82-(AH13-AH7) -> 68 | AL10: KUZNETSOV | AM10: 24 | AN10: KELLER | AO10: 63 | AR10: 193 | AT10: 192
A11: 10 | B11: REICHEL | C11: 16 | D11: KADRI | E11: 75 | F11: STONE | G11: 53 | H11: ZACHA | I11: 59 | J11: SKINNER | K11: 46 | L11: KOPITAR | M11: 70 | N11: DEBRUSK | O11: 40 | P11: REINHART | Q11: 94 | R11: BATHERSON | S11: 66 | T11: BENNETT | U11: 41 | V11: MCCANN | W11: 62 | X11: ZIBANEJAD | Y11: 72 | AA11: MOROTTI | AB11: =SUMPRODUCT(LARGE(U2:U13,{1;2;3;4;5;6;7;8})) -> 605 | AC11: =SUMPRODUCT(LARGE(U14:U18,{1;2;3})) -> 147 | AD11: =LARGE(U19:U20,1) -> 65 | AE11: =U21 -> 107 | AG11: Projection | AH11: =AH10*AH9 -> 62.848485 | AL11: MCTAVICH | AM11: 42 | AN11: JOHANSEN | AO11: 63
A12: 11 | B12: SMITH W. | C12: 0 | D12: KREIDER | E12: 75 | F12: STEPHENSON | G12: 51 | H12: DUCHENE | I12: 65 | J12: HARTMAN | K12: 45 | L12: BENN | M12: 60 | N12: ERIKSSON EK | O12: 64 | P12: MITTELSTADT | Q12: 57 | R12: BARBASHEV | S12: 45 | T12: HALL | U12: 4 | V12: PERFETTI | W12: 38 | X12: HAYTON | Y12: 10 | AA12: HENAULT | AB12: =SUMPRODUCT(LARGE(W2:W13,{1;2;3;4;5;6;7;8})) -> 486 | AC12: =SUMPRODUCT(LARGE(W14:W18,{1;2;3})) -> 150 | AD12: =LARGE(W19:W20,1) -> 83 | AE12: =W21 -> 110 | AL12: BERTUZZI | AM12: 43 | AN12: DUBE | AO12: 32
A13: 12 | B13: SCHMALTZ | C13: 61 | D13: STROME D. | E13: 67 | F13: COUTURE | G13: 1 | H13: LAFRENIERE | I13: 57 | J13: TIPPETT | K13: 53 | L13: NOVAK | M13: 45 | N13: WRIGHT | O13: 5 | P13: BURAKOVSKY | Q13: 16 | R13: DROUIN | S13: 56 | T13: RAKELL | U13: 37 | V13: KALIYEV | W13: 15 | X13: HERTL | Y13: 38 | AA13: DIEGO | AB13: =SUMPRODUCT(LARGE(Y2:Y13,{1;2;3;4;5;6;7;8})) -> 640 | AC13: =SUMPRODUCT(LARGE(Y14:Y18,{1;2;3})) -> 180 | AD13: =LARGE(Y19:Y20,1) -> 68 | AE13: =Y21 -> 104 | AG13: Hawks GP | AH13: 80 | AL13: DEBRINCAT | AM13: 67 | AN13: VORACEK | AO13: 62
A14: 1 | B14: SANDERSON | C14: 38 | D14: FOX | E14: 73 | F14: HAMILTON | G14: 16 | H14: HEISKANEN | I14: 54 | J14: SERGACHEV | K14: 19 | L14: HUGHES Q. | M14: 92 | N14: HUGHES L. | O14: 47 | P14: TOEWS D. | Q14: 50 | R14: MILLER KA. | S14: 30 | T14: MORRISSEY | U14: 69 | V14: DOBSON | W14: 70 | X14: DUNN | Y14: 46 | AL14: REINHART | AM14: 94 | AN14: RADULOV | AO14: 22
A15: 2 | B15: DRYSDALE | C15: 10 | D15: DAHLIN | E15: 59 | F15: MAKAR | G15: 90 | H15: SEIDER | I15: 42 | J15: JOSI | K15: 85 | L15: RIELLY | M15: 58 | N15: HEDMAN | O15: 76 | P15: NURSE | Q15: 32 | R15: ANDERSSON | S15: 39 | T15: DEANGELO | U15: 11 | V15: MCAVOY | W15: 47 | X15: THEODORE | Y15: 42 | AL15: MITTELSTADT | AM15: 56 | AN15: ARVIDSSON | AO15: 49
A16: 3 | B16: MATHESON | C16: 62 | D16: DOUGHTY | E16: 50 | F16: ADDISON | G16: 17 | H16: WERENSKI | I16: 57 | J16: EKBLAD | K16: 18 | L16: KLINGBERG | M16: 5 | N16: FOWLER | O16: 39 | P16: CARLSON | Q16: 52 | R16: JONES S. | S16: 31 | T16: EKHOLM | U16: 45 | V16: POWER | W16: 33 | X16: CHABOT | Y16: 30 | AL16: BURAKOVSKY | AM16: 16 | AN16: ZUCCARELLO | AO16: 79
A17: 4 | B17: CLARKE | C17: 6 | D17: SANDIN | E17: 23 | F17: FAULK | G17: 30 | H17: KARLSSON E. | I17: 56 | J17: CHYCHRUN | K17: 41 | L17: BURNS | M17: 43 | N17: LETANG | O17: 51 | P17: DURZI | Q17: 41 | R17: FORSLING | S17: 39 | T17: PIETRANGELO | U17: 33 | V17: BYRAM | W17: 29 | X17: BOUCHARD | Y17: 82 | AM17: 552 | AO17: 550
A18: 5 | B18: ZELLWEGER | C18: 9 | D18: MOSER | E18: 26 | F18: GUHLE | G18: 22 | H18: MONTOUR | I18: 33 | J18: LINDHOLM H. | K18: 26 | L18: SEVERSON | M18: 28 | N18: HRONEK | O18: 48 | P18: GIRARD | Q18: 18 | R18: VALIMAKI | S18: 17 | T18: ORLOV | U18: 26 | V18: BARRIE | W18: 15 | X18: WEEGAR | Y18: 52
A19: 1 | B19: HELLEBUYCK | C19: 93 | D19: BINNINGTON | E19: 76 | F19: ULLMARK | G19: 60 | H19: GEORGIEV | I19: 91 | J19: SAROS | K19: 88 | L19: MARKSTROM | M19: 64 | N19: BOBROVSKY | O19: 98 | P19: JARRY | Q19: 72 | R19: HUSSO | S19: 22 | T19: ANDERSEN | U19: 37 | V19: SKINNER S. | W19: 83 | X19: SWAYMAN | Y19: 68
A20: 2 | B20: VASILEVSKY | C20: 72 | D20: OETTINGER | E20: 83 | F20: KUEMPER | G20: 34 | H20: LEVI | I20: 22 | J20: GUSTAVSSON | K20: 56 | L20: SHESTERKIN | M20: 88 | N20: KORPISALO | O20: 48 | P20: SOROKIN | Q20: 71 | R20: COPLEY | S20: 13 | T20: SAMSONOV | U20: 65 | V20: HILL | W20: 48 | X20: VANECEK | Y20: 39
A21: 1 | B21: CHICAGO | C21: 52 | D21: VEGAS | E21: 98 | F21: DALLAS | G21: 113 | H21: NEW JERSEY | I21: 81 | J21: TORONTO | K21: 102 | L21: CAROLINA | M21: 111 | N21: TAMPA BAY | O21: 98 | P21: BOSTON | Q21: 109 | R21: SAN JOSE | S21: 47 | T21: COLORADO | U21: 107 | V21: FLORIDA | W21: 110 | X21: EDMONTON | Y21: 104
C22: =VLOOKUP(B1,PTS!C:H,6,FALSE) -> 702 | E22: =VLOOKUP(D1,PTS!$C:$H,6,FALSE) -> 1003 | G22: =VLOOKUP(F1,PTS!$C:$H,6,FALSE) -> 951 | I22: =VLOOKUP(H1,PTS!$C:$H,6,FALSE) -> 938 | K22: =VLOOKUP(J1,PTS!$C:$H,6,FALSE) -> 918 | M22: =VLOOKUP(L1,PTS!$C:$H,6,FALSE) -> 1036 | O22: =VLOOKUP(N1,PTS!$C:$H,6,FALSE) -> 933 | Q22: =VLOOKUP(P1,PTS!$C:$H,6,FALSE) -> 879 | S22: =VLOOKUP(R1,PTS!$C:$H,6,FALSE) -> 765 | U22: =VLOOKUP(T1,PTS!$C:$H,6,FALSE) -> 924 | W22: =VLOOKUP(V1,PTS!$C:$H,6,FALSE) -> 829 | Y22: =VLOOKUP(X1,PTS!$C:$H,6,FALSE) -> 992
B31: =D2 -> TARASENKO | C31: =E2 -> 55
B32: =D3 -> PANARIN | C32: =E3 -> 120
B33: =D4 -> STAMKOS | C33: =E4 -> 81
B34: =D5 -> TUCH | C34: =E5 -> 59
B35: =D6 -> KYROU | C35: =E6 -> 67
B36: =D7 -> NECAS | C36: =E7 -> 53
B37: =D8 -> THOMAS | C37: =E8 -> 86
B38: =D9 -> BOLDY | C38: =E9 -> 69
B39: =D10 -> LAINE | C39: =E10 -> 9
B40: =D11 -> KADRI | C40: =E11 -> 75
B41: =D12 -> KREIDER | C41: =E12 -> 75
B42: =D13 -> STROME D. | C42: =E13 -> 67
... B50: =D21 -> VEGAS | C50: =E21 -> 98
B51: =F2 -> TOFFOLI | C51: =G2 -> 55
B52: =F3 -> KUCHEROV | C52: =G3 -> 144
B53: =F4 -> PETTERSSON | C53: =G4 -> 89
B54: =F5 -> CROSBY | C54: =G5 -> 94
B55: =F6 -> OVECHKIN | C55: =G6 -> 65
...

Sheet 23
A1: 2023 | B1: PICARD | D1: CHABOT | F1: BEAUCHEMIN | H1: BLIER | J1: DIEGO | L1: LESSARD | N1: ROBB | P1: MOROTTI | R1: HENAULT | T1: MIOUSSE | V1: CONSTANTIN | X1: DESROSIERS | AB1: F | AC1: D | AD1: G | AE1: T | AG1: NEW | AI1: 2022 OLD
A2: 1 | B2: MILLER JT | C2: 82 | D2: STAMKOS | E2: 84 | F2: ZIBANEJAD | G2: 91 | H2: TERRY | I2: 61 | J2: CONNOR | K2: 81 | L2: KANE P. | M2: 57 | N2: MARNER | O2: 99 | P2: MACKINNON | Q2: 111 | R2: GAUDREAU | S2: 74 | T2: MATTHEWS | U2: 85 | V2: DRAISAITL | W2: 128 | X2: MCDAVID | Y2: 153 | AA2: PICARD | AB2: =SUMPRODUCT(LARGE(C2:C13,{1;2;3;4;5;6;7;8})) -> 610 | AC2: =SUMPRODUCT(LARGE(C14:C18,{1;2;3})) -> 133 | AD2: =LARGE(C19:C20,1) -> 103 | AE2: =C21 -> 91 | AG2: STAMKOS | AH2: 84 | AI2: DRAISAITL | AJ2: 110
A3: 2 | B3: KAPRIZOV | C3: 75 | D3: TKACHUK M | E3: 109 | F3: BARKOV | G3: 78 | H3: OVECHKIN | I3: 75 | J3: RANTANEN | K3: 105 | L3: TAVARES | M3: 80 | N3: KADRI | O3: 56 | P3: TKACHUK B | Q3: 83 | R3: EICHEL | S3: 66 | T3: DUCHENE | U3: 56 | V3: HUBERDEAU | W3: 55 | X3: MARCHAND | Y3: 67 | AA3: CHABOT | AB3: =SUMPRODUCT(LARGE(E2:E13,{1;2;3;4;5;6;7;8})) -> 613 | AC3: =SUMPRODUCT(LARGE(E14:E18,{1;2;3})) -> 186 | AD3: =LARGE(E19:E20,1) -> 102 | AE3: =E21 -> 109 | AG3: TKACHUK M | AH3: 109 | AI3: DEBRINCAT | AJ3: 78
A4: 3 | B4: LINDHOLM E. | C4: 64 | D4: DEBRINCAT | E4: 66 | F4: FIALA | G4: 72 | H4: CROSBY | I4: 93 | J4: REINHART | K4: 67 | L4: SVECHNIKOV | M4: 55 | N4: HINTZ | O4: 75 | P4: MARCHESSAULT | Q4: 57 | R4: FORSBERG | S4: 42 | T4: GUENTZEL | U4: 73 | V4: PAVELSKI | W4: 77 | X4: KUCHEROV | Y4: 112 | AA4: BEAUCHEMIN | AB4: =SUMPRODUCT(LARGE(G2:G13,{1;2;3;4;5;6;7;8})) -> 613 | AC4: =SUMPRODUCT(LARGE(G14:G18,{1;2;3})) -> 192 | AD4: =LARGE(G19:G20,1) -> 88 | AE4: =G21 -> 81 | AG4: DEBRINCAT | AH4: 66 | AI4: KOPITAR | AJ4: 67
A5: 4 | B5: ROBERTSON | C5: 109 | D5: THOMAS | E5: 65 | F5: LARKIN | G5: 79 | H5: BUCHNEVICH | I5: 67 | J5: MEIER | K5: 66 | L5: KELLER | M5: 86 | N5: TERAVAINEN | O5: 37 | P5: BARZAL | Q5: 51 | R5: JOHNSON K. | S5: 40 | T5: AHO | U5: 67 | V5: WHEELER | W5: 55 | X5: BERGERON | Y5: 58 | AA5: BLIER | AB5: =SUMPRODUCT(LARGE(I2:I13,{1;2;3;4;5;6;7;8})) -> 661 | AC5: =SUMPRODUCT(LARGE(I14:I18,{1;2;3})) -> 181 | AD5: =LARGE(I19:I20,1) -> 44 | AE5: =I21 -> 113 | AG5: THOMAS | AH5: 65 | AI5: ERIKSSON EK | AJ5: 50
A6: 5 | B6: SCHEIFELE | C6: 68 | D6: KYROU | E6: 73 | F6: HISCHIER | G6: 80 | H6: PETTERSSON | I6: 102 | J6: HUGHES J. | K6: 99 | L6: JOHANSEN | M6: 28 | N6: LANDESKOG | O6: 0 | P6: POINT | Q6: 95 | R6: NORRIS | S6: 3 | T6: PASTRNAK | U6: 113 | V6: SMITH R. | W6: 56 | X6: GIROUX | Y6: 79 | AA6: DIEGO | AB6: =SUMPRODUCT(LARGE(K2:K13,{1;2;3;4;5;6;7;8})) -> 648 | AC6: =SUMPRODUCT(LARGE(K14:K18,{1;2;3})) -> 146 | AD6: =LARGE(K19:K20,1) -> 89 | AE6: =K21 -> 93 | AG6: KYROU | AH6: 73 | AI6: TKACHUK M. | AJ6: 104
A7: 6 | B7: ZEGRAS | C7: 65 | D7: SUZUKI | E7: 66 | F7: STUTZLE | G7: 90 | H7: SCHENN | I7: 65 | J7: DACH | K7: 38 | L7: VORACEK | M7: 6 | N7: SCHWARTZ | O7: 40 | P7: RUST | Q7: 46 | R7: ROSLOVIC | S7: 44 | T7: EHLERS | U7: 38 | V7: HORVAT | W7: 70 | X7: SEGUIN | Y7: 50 | AA7: LESSARD | AB7: =SUMPRODUCT(LARGE(M2:M13,{1;2;3;4;5;6;7;8})) -> 523 | AC7: =SUMPRODUCT(LARGE(M14:M18,{1;2;3})) -> 151 | AD7: =LARGE(M19:M20,1) -> 75 | AE7: =M21 -> 95 | AG7: SUZUKI | AH7: 66 | AI7: LAINE | AJ7: 56
A8: 7 | B8: BACKSTROM | C8: 21 | D8: DUBOIS | E8: 63 | F8: CAUFIELD | G8: 36 | H8: VERHAEGHE | I8: 73 | J8: NYLANDER | K8: 87 | L8: PERRON | M8: 56 | N8: KAKKO | O8: 40 | P8: BENNETT | Q8: 40 | R8: CIRELLI | S8: 29 | T8: SHARANGOVICH | U8: 30 | V8: PACIORETTY | W8: 3 | X8: MALKIN | Y8: 83 | AA8: ROBB | AB8: =SUMPRODUCT(LARGE(O2:O13,{1;2;3;4;5;6;7;8})) -> 478 | AC8: =SUMPRODUCT(LARGE(O14:O18,{1;2;3})) -> 164 | AD8: =LARGE(O19:O20,1) -> 73 | AE8: =O21 -> 92 | AG8: DUBOIS | AH8: 63 | AI8: DUBOIS | AJ8: 60
A9: 8 | B9: KANE E. | C9: 28 | D9: LAINE | E9: 52 | F9: ERIKSSON EK | G9: 61 | H9: STONE | I9: 38 | J9: RAYMOND | K9: 45 | L9: ARVIDSSON | M9: 59 | N9: BYFIELD | O9: 22 | P9: MANTHA | Q9: 27 | R9: THOMPSON | S9: 94 | T9: HAYES | U9: 54 | V9: KARLSSON W. | W9: 53 | X9: PANARIN | Y9: 92 | AA9: MOROTTI | AB9: =SUMPRODUCT(LARGE(Q2:Q13,{1;2;3;4;5;6;7;8})) -> 551 | AC9: =SUMPRODUCT(LARGE(Q14:Q18,{1;2;3})) -> 100 | AD9: =LARGE(Q19:Q20,1) -> 93 | AE9: =Q21 -> 98 | AG9: LAINE | AH9: 52 | AI9: SUZUKI | AJ9: 61
A10: 9 | B10: KREIDER | C10: 54 | D10: NECAS | E10: 71 | F10: LAFRENIERE | G10: 39 | H10: VRANA | I10: 16 | J10: HYMAN | K10: 83 | L10: KUZNETSOV | M10: 55 | N10: BUNTING | O10: 49 | P10: ZUCCARELLO | Q10: 67 | R10: MANGIAPANE | S10: 43 | T10: BENIERS | U10: 57 | V10: COUTURIER | W10: 0 | X10: TARASENKO | Y10: 50 | AA10: HENAULT | AB10: =SUMPRODUCT(LARGE(S2:S13,{1;2;3;4;5;6;7;8})) -> 450 | AC10: =SUMPRODUCT(LARGE(S14:S18,{1;2;3})) -> 160 | AD10: =LARGE(S19:S20,1) -> 88 | AE10: =S21 -> 111 | AG10: NECAS | AH10: 71 | AI10: THOMAS | AJ10: 77
A11: 10 | B11: KOPITAR | C11: 74 | D11: BOLDY | E11: 63 | F11: BATHERSON | G11: 62 | H11: HERTL | I11: 63 | J11: JARVIS | K11: 39 | L11: BERTUZZI | M11: 30 | N11: BOESER | O11: 55 | P11: HALL | Q11: 36 | R11: LUNDELL | S11: 33 | T11: O'REILLY | U11: 30 | V11: BRATT | W11: 73 | X11: STROME R. | Y11: 41 | AA11: MIOUSSE | AB11: =SUMPRODUCT(LARGE(U2:U13,{1;2;3;4;5;6;7;8})) -> 572 | AC11: =SUMPRODUCT(LARGE(U14:U18,{1;2;3})) -> 150 | AD11: =LARGE(U19:U20,1) -> 97 | AE11: =U21 -> 103 | AG11: BOLDY | AH11: 63 | AI11: FARABEE | AJ11: 34
